Workbook

Sheet Normative data
B2: Regression Based Normative Data
B4: Please fill in the relevant independent variables:
B6: Age | C6: 60 | D6: Years
B7: Sex | C7: 1 | D7: Male = 0; Female = 1
B8: Years of Education | C8: 12 | D8: Years
B11: Please fill in the raw test score: | D11: Predicted Test score | E11: Residual | F11: Residual Standard Error | G11: z score | H11: Estimated percentile rank
B12: RAVLT Learning | C12: 1 | D12: =RAVLT_Learning!C27 -> 44.613725 | E12: =RAVLT_Learning!C33 -> -43.613725 | F12: =RAVLT_Learning!J34 -> 7.881973 | G12: =RAVLT_Learning!C34 -> -5.5333512 | H12: =SD_PERC_RAVLTL!T6 -> 0
B13: RAVLT Delayed | C13: 1 | D13: =RAVLT_Delayed!C27 -> 8.8981358 | E13: =RAVLT_Delayed!C33 -> -7.8981358 | F13: =RAVLT_Delayed!J34 -> 2.804785 | G13: =RAVLT_Delayed!C34 -> -2.8159505 | H13: =SD_PERC_RAVLTD!T6 -> 0
B14: Digit Span Forward | C14: 1 | D14: =DigDir!C27 -> 5.9085465 | E14: =DigDir!C34 -> -4.7566201 | F14: =DigDir!J34 -> 1.03194 | G14: =DigDir!C34 -> -4.7566201 | H14: =SD_PERC_DigDir!T6 -> 0
B15: Digit Span Backward | C15: 1 | D15: =DigInv!C27 -> 4.2774111 | E15: =DigInv!C33 -> -3.2774111 | F15: =DigInv!J34 -> 0.81645672 | G15: =DigInv!C34 -> -4.0141884 | H15: =SD_PERC_DigInv!T6 -> 0
B16: Trail Making Test A | C16: 1 | D16: =TMTA!C27 -> 3.4821742 | E16: =TMTA!C33 -> -3.4821742 | F16: =TMTA!J34 -> 0.335764 | G16: =TMTA!C34 -> 10.370898 | H16: =SD_PERC_TMTA!T6 -> 100
B17: Trail Making Test B | C17: 1 | D17: =TMTB!C27 -> 4.4113913 | E17: =TMTB!C33 -> -4.4113913 | F17: =TMTB!J34 -> 0.371282 | G17: =TMTB!C34 -> 11.881511 | H17: =SD_PERC_TMTB!T6 -> 100
B18: Semantic Fluency | C18: 1 | D18: =SEM!C27 -> 20.803766 | E18: =SEM!C33 -> -19.803766 | F18: =SEM!J34 -> 4.412897 | G18: =SEM!C34 -> -4.4877018 | H18: =SD_PERC_SEM!T6 -> 0
B19: Phonological Fluency | C19: 1 | D19: =FONO!C27 -> 17.024135 | E19: =FONO!C33 -> -16.024135 | F19: =FONO!J34 -> 4.334933 | G19: =FONO!C34 -> -3.6965127 | H19: =SD_PERC_FONO!T6 -> 0
C43: TMTA | D43: =LN(C16) -> 0
C44: TMTB | D44: =LN(C17) -> 0

Sheet RAVLT_Learning
B1: ONLY MAKE CHANGES IN THE GREY HIGHLIGHTED CELLS | I1: =SD_PERC_RAVLTL!A42
A3: 1 | B3: COPY-PASTE FINAL STAGE 1 MEAN PREDICTION FUNCTION HERE: | H3: 2 | I3: COPY-PASTE FINAL STAGE 1 VARIANCE PREDICTION FUNCTION HERE: | L3: 3 | M3: COPY-PASTE PERCENTILE RANKS DELTA HERE:
C5: Estimate | H5: A | I5: Assuming homoscedasticity | M5: Delta | N5: Percentile rank
B6: (Intercept) | C6: 29.543437 | I6: Residual variance | J6: 62.125498 | M6: -2.648687 | N6: 0
B7: ageC | C7: -0.43731309 | M7: -2.5960841 | N7: 0.1
B8: sexM | C8: 4.6162081 | M8: -2.5434813 | N8: 0.2
B9: years_education | C9: 0.46009904 | H9: B | I9: Not assuming homoscedasticity, prediction-specific residual variances: | M9: -2.507786 | N9: 0.3
I10: Predicted test score | J10: Residual variance | M10: -2.492841 | N10: 0.4
M11: -2.477896 | N11: 0.5
M12: -2.4498999 | N12: 0.6
M13: -2.4204207 | N13: 0.7
M14: -2.3832518 | N14: 0.8
M15: -2.3316082 | N15: 0.9
M16: -2.2799645 | N16: 1
M17: -2.1971929 | N17: 1.1
M18: -2.1064398 | N18: 1.2
M19: -2.0358747 | N19: 1.3
M20: -2.0275557 | N20: 1.4
M21: -2.0192366 | N21: 1.5
M22: -2.0048645 | N22: 1.6
... M24: -1.9693788 | N24: 1.8
H25: C | I25: Not assuming homoscedasticity, continuous variance prediction function: | M25: -1.9425327 | N25: 1.9
J26: Estimate | M26: -1.9156866 | N26: 2
A27: 4 | B27: Predicted test score: | C27: =C6+(C7*('Normative data'!C6-71.28))+(RAVLT_Learning!C8*'Normative data'!C7)+(C9*'Normative data'!C8) -> 44.613725 | M27: -1.904304 | N27: 2.1
B28: [SPECIFY THE APPROPRIATE FORMULA IN CELL B27 TO COMPUTE | M28: -1.9035858 | N28: 2.2
B29: THE PREDICTED TEST SCORE BASED ON THE INPUT PROVIDED | M29: -1.9027496 | N29: 2.3
B30: IN SHEET 1 (E.G. SPECIFIED GENDER) + COPY-PASTED STAGE 1 MODEL] | M30: -1.8991373 | N30: 2.4
M31: -1.895525 | N31: 2.5
M32: -1.8891374 | N32: 2.6
B33: Computed residual: | C33: ='Normative data'!C12-RAVLT_Learning!C27 -> -43.613725 | M33: -1.8798587 | N33: 2.7
B34: Std. Residual: | C34: =C33/SD_PERC_RAVLTL!I38 -> -5.5333512 | I34: Residual Std.Error to be used: | J34: =SD_PERC_RAVLTL!I38 -> 7.881973 | M34: -1.8705801 | N34: 2.8
M35: -1.8517585 | N35: 2.9
M36: -1.8323145 | N36: 3
M37: -1.8188712 | N37: 3.1
M38: -1.8149025 | N38: 3.2
M39: -1.8109339 | N39: 3.3
M40: -1.8014002 | N40: 3.4
M41: -1.7907805 | N41: 3.5
M42: -1.7831526 | N42: 3.6
M43: -1.783004 | N43: 3.7
...

Sheet SEM
B1: ONLY MAKE CHANGES IN THE GREY HIGHLIGHTED CELLS | I1: =SD_PERC_SEM!A42
A3: 1 | B3: COPY-PASTE FINAL STAGE 1 MEAN PREDICTION FUNCTION HERE: | H3: 2 | I3: COPY-PASTE FINAL STAGE 1 VARIANCE PREDICTION FUNCTION HERE: | L3: 3 | M3: COPY-PASTE PERCENTILE RANKS DELTA HERE:
C5: Estimate | H5: A | I5: Assuming homoscedasticity | M5: Delta | N5: Percentile rank
B6: (Intercept) | C6: 11.192933 | I6: Residual variance | J6: 19.47366 | M6: -2.560887 | N6: 0
B7: age_log_100 | C7: -13.211326 | M7: -2.4942776 | N7: 0.1
B8: years_education | C8: 0.23851236 | M8: -2.4276682 | N8: 0.2
H9: B | I9: Not assuming homoscedasticity, prediction-specific residual variances: | M9: -2.3783523 | N9: 0.3
I10: Predicted test score | J10: Residual variance | M10: -2.3502604 | N10: 0.4
M11: -2.3221685 | N11: 0.5
M12: -2.2893405 | N12: 0.6
M13: -2.2559742 | N13: 0.7
M14: -2.2069538 | N14: 0.8
M15: -2.1284668 | N15: 0.9
M16: -2.0499798 | N16: 1
M17: -2.0222876 | N17: 1.1
M18: -2.0076197 | N18: 1.2
M19: -1.9963965 | N19: 1.3
M20: -1.9957944 | N20: 1.4
M21: -1.9951923 | N21: 1.5
M22: -1.9522825 | N22: 1.6
... M24: -1.8323742 | N24: 1.8
H25: C | I25: Not assuming homoscedasticity, continuous variance prediction function: | M25: -1.7934905 | N25: 1.9
J26: Estimate | M26: -1.7546069 | N26: 2
A27: 4 | B27: Predicted test score: | C27: =$C$6 + $C$7 * LN('Normative data'!$C$6/100) + $C$8 * 'Normative data'!$C$8 -> 20.803766 | M27: -1.7306629 | N27: 2.1
B28: [SPECIFY THE APPROPRIATE FORMULA IN CELL B27 TO COMPUTE | M28: -1.717022 | N28: 2.2
B29: THE PREDICTED TEST SCORE BASED ON THE INPUT PROVIDED | M29: -1.7039287 | N29: 2.3
B30: IN SHEET 1 (E.G. SPECIFIED GENDER) + COPY-PASTED STAGE 1 MODEL] | M30: -1.7037014 | N30: 2.4
M31: -1.703474 | N31: 2.5
M32: -1.6905915 | N32: 2.6
B33: Computed residual: | C33: ='Normative data'!C18-SEM!C27 -> -19.803766 | M33: -1.6645267 | N33: 2.7
B34: Std. Residual: | C34: =(C33/SD_PERC_SEM!I38) -> -4.4877018 | I34: Residual Std.Error to be used: | J34: =SD_PERC_SEM!I38 -> 4.412897 | M34: -1.6384618 | N34: 2.8
M35: -1.6323598 | N35: 2.9
M36: -1.6275598 | N36: 3
M37: -1.6206199 | N37: 3.1
M38: -1.6103013 | N38: 3.2
M39: -1.5999827 | N39: 3.3
M40: -1.5913608 | N40: 3.4
M41: -1.58307 | N41: 3.5
M42: -1.5743004 | N42: 3.6
M43: -1.5643338 | N43: 3.7
...

Sheet SD_PERC_SEM
A1: Determine SD(residual) to use; DO NOT MAKE CHANGES HERE | L1: Determine percentile
A3: Assuming homoscedasticity | G3: =SQRT(SEM!J6) -> 4.412897
L4: =RAVLT_Learning!M5 -> Delta | M4: =RAVLT_Learning!N5 -> Percentile rank | O4: Abs diff delta | P4: Percentile
L5: =SEM!M6 -> -2.560887 | M5: =SEM!N6 -> 0 | O5: =ABS(L5-SEM!$C$34) -> 1.9268148 | P5: =M5 -> 0 | R5: Min abs delta | T5: =MIN(O5:O1006) -> 1.9268148
A6: Not assuming homoscedasticity, residual std.error per group: | L6: =SEM!M7 -> -2.4942776 | M6: =SEM!N7 -> 0.1 | O6: =ABS(L6-SEM!$C$34) -> 1.9934242 | P6: =M6 -> 0.1 | R6: Percentile | T6: =VLOOKUP(T5, O5:P1006, 2, ) -> 0
L7: =SEM!M8 -> -2.4276682 | M7: =SEM!N8 -> 0.2 | O7: =ABS(L7-SEM!$C$34) -> 2.0600336 | P7: =M7 -> 0.2
A8: Predicted score: | B8: =SEM!C27 -> 20.803766
L9: =SEM!M9 -> -2.3783523 | M9: =SEM!N9 -> 0.3 | O9: =ABS(L9-SEM!$C$34) -> 2.1093495 | P9: =M9 -> 0.3
B10: =RAVLT_Learning!J10 -> Residual variance | C10: =RAVLT_Learning!I10 -> Predicted test score | L10: =SEM!M10 -> -2.3502604 | M10: =SEM!N10 -> 0.4 | O10: =ABS(L10-SEM!$C$34) -> 2.1374414 | P10: =M10 -> 0.4
B11: =SEM!J11 -> 0 | C11: =SEM!I11 -> 0 | L11: =SEM!M11 -> -2.3221685 | M11: =SEM!N11 -> 0.5 | O11: =ABS(L11-SEM!$C$34) -> 2.1655332 | P11: =M11 -> 0.5
B12: =SEM!J12 -> 0 | C12: =SEM!I12 -> 0 | L12: =SEM!M12 -> -2.2893405 | M12: =SEM!N12 -> 0.6 | O12: =ABS(L12-SEM!$C$34) -> 2.1983613 | P12: =M12 -> 0.6
B13: =SEM!J13 -> 0 | C13: =SEM!I13 -> 0 | L13: =SEM!M13 -> -2.2559742 | M13: =SEM!N13 -> 0.7 | O13: =ABS(L13-SEM!$C$34) -> 2.2317276 | P13: =M13 -> 0.7
B14: =SEM!J14 -> 0 | C14: =SEM!I14 -> 0 | L14: =SEM!M14 -> -2.2069538 | M14: =SEM!N14 -> 0.8 | O14: =ABS(L14-SEM!$C$34) -> 2.280748 | P14: =M14 -> 0.8
B15: =SEM!J15 -> 0 | C15: =SEM!I15 -> 0 | L15: =SEM!M15 -> -2.1284668 | M15: =SEM!N15 -> 0.9 | O15: =ABS(L15-SEM!$C$34) -> 2.359235 | P15: =M15 -> 0.9
B16: =SEM!J16 -> 0 | C16: =SEM!I16 -> 0 | L16: =SEM!M16 -> -2.0499798 | M16: =SEM!N16 -> 1 | O16: =ABS(L16-SEM!$C$34) -> 2.437722 | P16: =M16 -> 1
B17: =SEM!J17 -> 0 | C17: =SEM!I17 -> 0 | L17: =SEM!M17 -> -2.0222876 | M17: =SEM!N17 -> 1.1 | O17: =ABS(L17-SEM!$C$34) -> 2.4654142 | P17: =M17 -> 1.1
B18: =SEM!J18 -> 0 | C18: =SEM!I18 -> 0 | L18: =SEM!M18 -> -2.0076197 | M18: =SEM!N18 -> 1.2 | O18: =ABS(L18-SEM!$C$34) -> 2.480082 | P18: =M18 -> 1.2
B19: =SEM!J19 -> 0 | C19: =SEM!I19 -> 0 | L19: =SEM!M19 -> -1.9963965 | M19: =SEM!N19 -> 1.3 | O19: =ABS(L19-SEM!$C$34) -> 2.4913052 | P19: =M19 -> 1.3
B20: =SEM!J20 -> 0 | C20: =SEM!I20 -> 0 | E20: Residual variance | G20: {=INDEX(B11:B22,MATCH(MIN(ABS(C11:C22-B8)),ABS(C11:C22-B8),0))} -> 0 | L20: =SEM!M20 -> -1.9957944 | M20: =SEM!N20 -> 1.4 | O20: =ABS(L20-SEM!$C$34) -> 2.4919073 | P20: =M20 -> 1.4
B21: =SEM!J21 -> 0 | C21: =SEM!I21 -> 0 | E21: Residual std. Error | G21: =SQRT(G20) -> 0 | L21: =SEM!M21 -> -1.9951923 | M21: =SEM!N21 -> 1.5 | O21: =ABS(L21-SEM!$C$34) -> 2.4925094 | P21: =M21 -> 1.5
B22: =SEM!J22 -> 0 | C22: =SEM!I22 -> 0 | L22: =SEM!M22 -> -1.9522825 | M22: =SEM!N22 -> 1.6 | O22: =ABS(L22-SEM!$C$34) -> 2.5354193 | P22: =M22 -> 1.6
E23: Formula, see: | F23: https://www.excel-easy.com/examples/closest-match.html | L23: =SEM!M23 -> -1.8907075 | M23: =SEM!N23 -> 1.7 | O23: =ABS(L23-SEM!$C$34) -> 2.5969942 | P23: =M23 -> 1.7
L24: =SEM!M24 -> -1.8323742 | M24: =SEM!N24 -> 1.8 | O24: =ABS(L24-SEM!$C$34) -> 2.6553276 | P24: =M24 -> 1.8
A25: Not assuming homoscedasticity, variance function | L25: =SEM!M25 -> -1.7934905 | M25: =SEM!N25 -> 1.9 | O25: =ABS(L25-SEM!$C$34) -> 2.6942112 | P25: =M25 -> 1.9
L26: =SEM!M26 -> -1.7546069 | M26: =SEM!N26 -> 2 | O26: =ABS(L26-SEM!$C$34) -> 2.7330949 | P26: =M26 -> 2
A27: =RAVLT_Learning!I26 | B27: =RAVLT_Learning!J26 -> Estimate | C27: X | D27: Beta x X | L27: =SEM!M27 -> -1.7306629 | M27: =SEM!N27 -> 2.1 | O27: =ABS(L27-SEM!$C$34) -> 2.7570389 | P27: =M27 -> 2.1
A28: =SEM!I27 -> 0 | B28: =SEM!J27 -> 0 | C28: 1 | D28: =B28*C28 -> 0 | L28: =SEM!M28 -> -1.717022 | M28: =SEM!N28 -> 2.2 | O28: =ABS(L28-SEM!$C$34) -> 2.7706797 | P28: =M28 -> 2.2
A29: =SEM!I28 -> 0 | B29: =SEM!J28 -> 0 | C29: =B8 -> 20.803766 | D29: =B29*C29 -> 0 | L29: =SEM!M29 -> -1.7039287 | M29: =SEM!N29 -> 2.3 | O29: =ABS(L29-SEM!$C$34) -> 2.783773 | P29: =M29 -> 2.3
A30: =SEM!I29 -> 0 | B30: =SEM!J29 -> 0 | C30: =B8^2 -> 432.79667 | D30: =B30*C30 -> 0 | L30: =SEM!M30 -> -1.7037014 | M30: =SEM!N30 -> 2.4 | O30: =ABS(L30-SEM!$C$34) -> 2.7840004 | P30: =M30 -> 2.4
A31: =SEM!I30 -> 0 | B31: =SEM!J30 -> 0 | C31: =B8^3 -> 9003.8004 | D31: =B31*C31 -> 0 | L31: =SEM!M31 -> -1.703474 | M31: =SEM!N31 -> 2.5 | O31: =ABS(L31-SEM!$C$34) -> 2.7842278 | P31: =M31 -> 2.5
A32: =SEM!I31 -> 0 | B32: =SEM!J31 -> 0 | C32: =B8^4 -> 187312.95 | D32: =B32*C32 -> 0 | L32: =SEM!M32 -> -1.6905915 | M32: =SEM!N32 -> 2.6 | O32: =ABS(L32-SEM!$C$34) -> 2.7971102 | P32: =M32 -> 2.6
A33: =SEM!I32 -> 0 | B33: =SEM!J32 -> 0 | C33: =B8^5 -> 3896814.8 | D33: =B33*C33 -> 0 | L33: =SEM!M33 -> -1.6645267 | M33: =SEM!N33 -> 2.7 | O33: =ABS(L33-SEM!$C$34) -> 2.8231751 | P33: =M33 -> 2.7
G34: =SQRT(D35) -> 0 | L34: =SEM!M34 -> -1.6384618 | M34: =SEM!N34 -> 2.8 | O34: =ABS(L34-SEM!$C$34) -> 2.84924 | P34: =M34 -> 2.8
B35: Predicted VARIANCE | D35: =SUM(D28:D34) -> 0 | L35: =SEM!M35 -> -1.6323598 | M35: =SEM!N35 -> 2.9 | O35: =ABS(L35-SEM!$C$34) -> 2.8553419 | P35: =M35 -> 2.9
L36: =SEM!M36 -> -1.6275598 | M36: =SEM!N36 -> 3 | O36: =ABS(L36-SEM!$C$34) -> 2.860142 | P36: =M36 -> 3
A37: Checks | L37: =SEM!M37 -> -1.6206199 | M37: =SEM!N37 -> 3.1 | O37: =ABS(L37-SEM!$C$34) -> 2.8670819 | P37: =M37 -> 3.1
A38: Overall resid std error entered | D38: =IF(G3>0, 1, 0) -> 1 | G38: Res. Std error | I38: =IF(D41=1, G3+G21+G34, ) -> 4.412897 | L38: =SEM!M38 -> -1.6103013 | M38: =SEM!N38 -> 3.2 | O38: =ABS(L38-SEM!$C$34) -> 2.8774005 | P38: =M38 -> 3.2
A39: Resid std per group | D39: =IF(G21>0, 1, 0) -> 0 | I39: =IF(D41=1, " ", "ERROR!") | L39: =SEM!M39 -> -1.5999827 | M39: =SEM!N39 -> 3.3 | O39: =ABS(L39-SEM!$C$34) -> 2.8877191 | P39: =M39 -> 3.3
A40: Variance function | D40: =IF(G34>0, 1, 0) -> 0 | L40: =SEM!M40 -> -1.5913608 | M40: =SEM!N40 -> 3.4 | O40: =ABS(L40-SEM!$C$34) -> 2.896341 | P40: =M40 -> 3.4
C41: Som | D41: =SUM(D38:D40) -> 1 | E41: (check should be 1 to be OK) | L41: =SEM!M41 -> -1.58307 | M41: =SEM!N41 -> 3.5 | O41: =ABS(L41-SEM!$C$34) -> 2.9046318 | P41: =M41 -> 3.5
...

Sheet FONO
B1: ONLY MAKE CHANGES IN THE GREY HIGHLIGHTED CELLS | I1: =SD_PERC_FONO!A42
A3: 1 | B3: COPY-PASTE FINAL STAGE 1 MEAN PREDICTION FUNCTION HERE: | H3: 2 | I3: COPY-PASTE FINAL STAGE 1 VARIANCE PREDICTION FUNCTION HERE: | L3: 3 | M3: COPY-PASTE PERCENTILE RANKS DELTA HERE:
C5: Estimate | H5: A | I5: Assuming homoscedasticity | M5: Delta | N5: Percentile rank
B6: (Intercept) | C6: 9.3409387 | I6: Residual variance | J6: 18.791644 | M6: -2.871918 | N6: 0
B7: age_log_100 | C7: -5.412573 | M7: -2.8025658 | N7: 0.1
B8: sexM | C8: 1.9264357 | M8: -2.7332135 | N8: 0.2
B9: years_education | C9: 0.24932329 | H9: B | I9: Not assuming homoscedasticity, prediction-specific residual variances: | M9: -2.6241558 | N9: 0.3
I10: Predicted test score | J10: Residual variance | M10: -2.4663688 | N10: 0.4
M11: -2.3085817 | N11: 0.5
M12: -2.2779895 | N12: 0.6
M13: -2.2618513 | N13: 0.7
M14: -2.2329364 | N14: 0.8
M15: -2.1799713 | N15: 0.9
M16: -2.1270062 | N16: 1
M17: -2.0979625 | N17: 1.1
M18: -2.0750524 | N18: 1.2
M19: -2.0436432 | N19: 1.3
M20: -1.9860282 | N20: 1.4
M21: -1.9284132 | N21: 1.5
M22: -1.9058716 | N22: 1.6
... M24: -1.885827 | N24: 1.8
H25: C | I25: Not assuming homoscedasticity, continuous variance prediction function: | M25: -1.8374009 | N25: 1.9
J26: Estimate | M26: -1.7889748 | N26: 2
A27: 4 | B27: Predicted test score: | C27: =$C$6 + $C$7*LN('Normative data'!$C$6/100) + $C$8*('Normative data'!$C$7) + $C$9*('Normative data'!$C$8) -> 17.024135 | M27: -1.7562288 | N27: 2.1
B28: [SPECIFY THE APPROPRIATE FORMULA IN CELL B27 TO COMPUTE | M28: -1.7342968 | N28: 2.2
B29: THE PREDICTED TEST SCORE BASED ON THE INPUT PROVIDED | M29: -1.7123251 | N29: 2.3
B30: IN SHEET 1 (E.G. SPECIFIED GENDER) + COPY-PASTED STAGE 1 MODEL] | M30: -1.6894202 | N30: 2.4
M31: -1.6665152 | N31: 2.5
M32: -1.639772 | N32: 2.6
B33: Computed residual: | C33: ='Normative data'!C19-FONO!C27 -> -16.024135 | M33: -1.6090306 | N33: 2.7
B34: Std. Residual: | C34: =(C33/SD_PERC_FONO!I38) -> -3.6965127 | I34: Residual Std.Error to be used: | J34: =SD_PERC_FONO!I38 -> 4.334933 | M34: -1.5782891 | N34: 2.8
M35: -1.5597911 | N35: 2.9
M36: -1.5420915 | N36: 3
M37: -1.5301653 | N37: 3.1
M38: -1.5273551 | N38: 3.2
M39: -1.5245448 | N39: 3.3
M40: -1.5185198 | N40: 3.4
M41: -1.5118676 | N41: 3.5
M42: -1.5065144 | N42: 3.6
M43: -1.504409 | N43: 3.7
...

Sheet SD_PERC_FONO
A1: Determine SD(residual) to use; DO NOT MAKE CHANGES HERE | L1: Determine percentile
A3: Assuming homoscedasticity | G3: =SQRT(FONO!J6) -> 4.334933
L4: =RAVLT_Learning!M5 -> Delta | M4: =RAVLT_Learning!N5 -> Percentile rank | O4: Abs diff delta | P4: Percentile
L5: =FONO!M6 -> -2.871918 | M5: =FONO!N6 -> 0 | O5: =ABS(L5-FONO!$C$34) -> 0.82459469 | P5: =M5 -> 0 | R5: Min abs delta | T5: =MIN(O5:O1006) -> 0.82459469
A6: Not assuming homoscedasticity, residual std.error per group: | L6: =FONO!M7 -> -2.8025658 | M6: =FONO!N7 -> 0.1 | O6: =ABS(L6-FONO!$C$34) -> 0.89394693 | P6: =M6 -> 0.1 | R6: Percentile | T6: =VLOOKUP(T5, O5:P1006, 2, ) -> 0
L7: =FONO!M8 -> -2.7332135 | M7: =FONO!N8 -> 0.2 | O7: =ABS(L7-FONO!$C$34) -> 0.96329918 | P7: =M7 -> 0.2
A8: Predicted score: | B8: =FONO!C27 -> 17.024135
L9: =FONO!M9 -> -2.6241558 | M9: =FONO!N9 -> 0.3 | O9: =ABS(L9-FONO!$C$34) -> 1.0723569 | P9: =M9 -> 0.3
B10: =RAVLT_Learning!J10 -> Residual variance | C10: =RAVLT_Learning!I10 -> Predicted test score | L10: =FONO!M10 -> -2.4663688 | M10: =FONO!N10 -> 0.4 | O10: =ABS(L10-FONO!$C$34) -> 1.2301439 | P10: =M10 -> 0.4
B11: =FONO!J11 -> 0 | C11: =FONO!I11 -> 0 | L11: =FONO!M11 -> -2.3085817 | M11: =FONO!N11 -> 0.5 | O11: =ABS(L11-FONO!$C$34) -> 1.387931 | P11: =M11 -> 0.5
B12: =FONO!J12 -> 0 | C12: =FONO!I12 -> 0 | L12: =FONO!M12 -> -2.2779895 | M12: =FONO!N12 -> 0.6 | O12: =ABS(L12-FONO!$C$34) -> 1.4185232 | P12: =M12 -> 0.6
B13: =FONO!J13 -> 0 | C13: =FONO!I13 -> 0 | L13: =FONO!M13 -> -2.2618513 | M13: =FONO!N13 -> 0.7 | O13: =ABS(L13-FONO!$C$34) -> 1.4346614 | P13: =M13 -> 0.7
B14: =FONO!J14 -> 0 | C14: =FONO!I14 -> 0 | L14: =FONO!M14 -> -2.2329364 | M14: =FONO!N14 -> 0.8 | O14: =ABS(L14-FONO!$C$34) -> 1.4635763 | P14: =M14 -> 0.8
B15: =FONO!J15 -> 0 | C15: =FONO!I15 -> 0 | L15: =FONO!M15 -> -2.1799713 | M15: =FONO!N15 -> 0.9 | O15: =ABS(L15-FONO!$C$34) -> 1.5165414 | P15: =M15 -> 0.9
B16: =FONO!J16 -> 0 | C16: =FONO!I16 -> 0 | L16: =FONO!M16 -> -2.1270062 | M16: =FONO!N16 -> 1 | O16: =ABS(L16-FONO!$C$34) -> 1.5695065 | P16: =M16 -> 1
B17: =FONO!J17 -> 0 | C17: =FONO!I17 -> 0 | L17: =FONO!M17 -> -2.0979625 | M17: =FONO!N17 -> 1.1 | O17: =ABS(L17-FONO!$C$34) -> 1.5985502 | P17: =M17 -> 1.1
B18: =FONO!J18 -> 0 | C18: =FONO!I18 -> 0 | L18: =FONO!M18 -> -2.0750524 | M18: =FONO!N18 -> 1.2 | O18: =ABS(L18-FONO!$C$34) -> 1.6214603 | P18: =M18 -> 1.2
B19: =FONO!J19 -> 0 | C19: =FONO!I19 -> 0 | L19: =FONO!M19 -> -2.0436432 | M19: =FONO!N19 -> 1.3 | O19: =ABS(L19-FONO!$C$34) -> 1.6528695 | P19: =M19 -> 1.3
B20: =FONO!J20 -> 0 | C20: =FONO!I20 -> 0 | E20: Residual variance | G20: {=INDEX(B11:B22,MATCH(MIN(ABS(C11:C22-B8)),ABS(C11:C22-B8),0))} -> 0 | L20: =FONO!M20 -> -1.9860282 | M20: =FONO!N20 -> 1.4 | O20: =ABS(L20-FONO!$C$34) -> 1.7104845 | P20: =M20 -> 1.4
B21: =FONO!J21 -> 0 | C21: =FONO!I21 -> 0 | E21: Residual std. Error | G21: =SQRT(G20) -> 0 | L21: =FONO!M21 -> -1.9284132 | M21: =FONO!N21 -> 1.5 | O21: =ABS(L21-FONO!$C$34) -> 1.7680994 | P21: =M21 -> 1.5
B22: =FONO!J22 -> 0 | C22: =FONO!I22 -> 0 | L22: =FONO!M22 -> -1.9058716 | M22: =FONO!N22 -> 1.6 | O22: =ABS(L22-FONO!$C$34) -> 1.7906411 | P22: =M22 -> 1.6
E23: Formula, see: | F23: https://www.excel-easy.com/examples/closest-match.html | L23: =FONO!M23 -> -1.8988034 | M23: =FONO!N23 -> 1.7 | O23: =ABS(L23-FONO!$C$34) -> 1.7977093 | P23: =M23 -> 1.7
L24: =FONO!M24 -> -1.885827 | M24: =FONO!N24 -> 1.8 | O24: =ABS(L24-FONO!$C$34) -> 1.8106857 | P24: =M24 -> 1.8
A25: Not assuming homoscedasticity, variance function | L25: =FONO!M25 -> -1.8374009 | M25: =FONO!N25 -> 1.9 | O25: =ABS(L25-FONO!$C$34) -> 1.8591118 | P25: =M25 -> 1.9
L26: =FONO!M26 -> -1.7889748 | M26: =FONO!N26 -> 2 | O26: =ABS(L26-FONO!$C$34) -> 1.9075379 | P26: =M26 -> 2
A27: =RAVLT_Learning!I26 | B27: =RAVLT_Learning!J26 -> Estimate | C27: X | D27: Beta x X | L27: =FONO!M27 -> -1.7562288 | M27: =FONO!N27 -> 2.1 | O27: =ABS(L27-FONO!$C$34) -> 1.9402839 | P27: =M27 -> 2.1
A28: =FONO!I27 -> 0 | B28: =FONO!J27 -> 0 | C28: 1 | D28: =B28*C28 -> 0 | L28: =FONO!M28 -> -1.7342968 | M28: =FONO!N28 -> 2.2 | O28: =ABS(L28-FONO!$C$34) -> 1.9622159 | P28: =M28 -> 2.2
A29: =FONO!I28 -> 0 | B29: =FONO!J28 -> 0 | C29: =B8 -> 17.024135 | D29: =B29*C29 -> 0 | L29: =FONO!M29 -> -1.7123251 | M29: =FONO!N29 -> 2.3 | O29: =ABS(L29-FONO!$C$34) -> 1.9841876 | P29: =M29 -> 2.3
A30: =FONO!I29 -> 0 | B30: =FONO!J29 -> 0 | C30: =B8^2 -> 289.82117 | D30: =B30*C30 -> 0 | L30: =FONO!M30 -> -1.6894202 | M30: =FONO!N30 -> 2.4 | O30: =ABS(L30-FONO!$C$34) -> 2.0070925 | P30: =M30 -> 2.4
A31: =FONO!I30 -> 0 | B31: =FONO!J30 -> 0 | C31: =B8^3 -> 4933.9546 | D31: =B31*C31 -> 0 | L31: =FONO!M31 -> -1.6665152 | M31: =FONO!N31 -> 2.5 | O31: =ABS(L31-FONO!$C$34) -> 2.0299975 | P31: =M31 -> 2.5
A32: =FONO!I31 -> 0 | B32: =FONO!J31 -> 0 | C32: =B8^4 -> 83996.309 | D32: =B32*C32 -> 0 | L32: =FONO!M32 -> -1.639772 | M32: =FONO!N32 -> 2.6 | O32: =ABS(L32-FONO!$C$34) -> 2.0567407 | P32: =M32 -> 2.6
A33: =FONO!I32 -> 0 | B33: =FONO!J32 -> 0 | C33: =B8^5 -> 1429964.5 | D33: =B33*C33 -> 0 | L33: =FONO!M33 -> -1.6090306 | M33: =FONO!N33 -> 2.7 | O33: =ABS(L33-FONO!$C$34) -> 2.0874821 | P33: =M33 -> 2.7
G34: =SQRT(D35) -> 0 | L34: =FONO!M34 -> -1.5782891 | M34: =FONO!N34 -> 2.8 | O34: =ABS(L34-FONO!$C$34) -> 2.1182236 | P34: =M34 -> 2.8
B35: Predicted VARIANCE | D35: =SUM(D28:D34) -> 0 | L35: =FONO!M35 -> -1.5597911 | M35: =FONO!N35 -> 2.9 | O35: =ABS(L35-FONO!$C$34) -> 2.1367216 | P35: =M35 -> 2.9
L36: =FONO!M36 -> -1.5420915 | M36: =FONO!N36 -> 3 | O36: =ABS(L36-FONO!$C$34) -> 2.1544212 | P36: =M36 -> 3
A37: Checks | L37: =FONO!M37 -> -1.5301653 | M37: =FONO!N37 -> 3.1 | O37: =ABS(L37-FONO!$C$34) -> 2.1663474 | P37: =M37 -> 3.1
A38: Overall resid std error entered | D38: =IF(G3>0, 1, 0) -> 1 | G38: Res. Std error | I38: =IF(D41=1, G3+G21+G34, ) -> 4.334933 | L38: =FONO!M38 -> -1.5273551 | M38: =FONO!N38 -> 3.2 | O38: =ABS(L38-FONO!$C$34) -> 2.1691576 | P38: =M38 -> 3.2
A39: Resid std per group | D39: =IF(G21>0, 1, 0) -> 0 | I39: =IF(D41=1, " ", "ERROR!") | L39: =FONO!M39 -> -1.5245448 | M39: =FONO!N39 -> 3.3 | O39: =ABS(L39-FONO!$C$34) -> 2.1719679 | P39: =M39 -> 3.3
A40: Variance function | D40: =IF(G34>0, 1, 0) -> 0 | L40: =FONO!M40 -> -1.5185198 | M40: =FONO!N40 -> 3.4 | O40: =ABS(L40-FONO!$C$34) -> 2.1779928 | P40: =M40 -> 3.4
C41: Som | D41: =SUM(D38:D40) -> 1 | E41: (check should be 1 to be OK) | L41: =FONO!M41 -> -1.5118676 | M41: =FONO!N41 -> 3.5 | O41: =ABS(L41-FONO!$C$34) -> 2.1846451 | P41: =M41 -> 3.5
...

Sheet TMTB
B1: ONLY MAKE CHANGES IN THE GREY HIGHLIGHTED CELLS | I1: =SD_PERC_TMTB!A42
A3: 1 | B3: COPY-PASTE FINAL STAGE 1 MEAN PREDICTION FUNCTION HERE: | H3: 2 | I3: COPY-PASTE FINAL STAGE 1 VARIANCE PREDICTION FUNCTION HERE: | L3: 3 | M3: COPY-PASTE PERCENTILE RANKS DELTA HERE:
C5: Estimate | H5: A | I5: Assuming homoscedasticity | M5: Delta | N5: Percentile rank
B6: (Intercept) | C6: 4.8926521 | I6: Residual variance | J6: 0.13785032 | M6: -2.719612 | N6: 0
B7: ageC | C7: 0.020027674 | M7: -2.5059802 | N7: 0.1
B8: years_education | C8: -0.019610076 | M8: -2.2923485 | N8: 0.2
H9: B | I9: Not assuming homoscedasticity, prediction-specific residual variances: | M9: -2.1481112 | N9: 0.3
I10: Predicted test score | J10: Residual variance | M10: -2.0890399 | N10: 0.4
M11: -2.0299687 | N11: 0.5
M12: -1.9608566 | N12: 0.6
M13: -1.8906036 | N13: 0.7
M14: -1.843478 | N14: 0.8
M15: -1.8398865 | N15: 0.9
M16: -1.836295 | N16: 1
M17: -1.832188 | N17: 1.1
M18: -1.8279489 | N18: 1.2
M19: -1.8242391 | N19: 1.3
M20: -1.8221611 | N20: 1.4
M21: -1.8200831 | N21: 1.5
M22: -1.8109601 | N22: 1.6
... M24: -1.7878513 | N24: 1.8
H25: C | I25: Not assuming homoscedasticity, continuous variance prediction function: | M25: -1.7850956 | N25: 1.9
J26: Estimate | M26: -1.7823398 | N26: 2
A27: 4 | B27: Predicted test score: | C27: =C6+(C7*('Normative data'!C6-72.28))+(TMTB!C8*'Normative data'!C8) -> 4.4113913 | M27: -1.7702799 | N27: 2.1
B28: [SPECIFY THE APPROPRIATE FORMULA IN CELL B27 TO COMPUTE | M28: -1.7518034 | N28: 2.2
B29: THE PREDICTED TEST SCORE BASED ON THE INPUT PROVIDED | M29: -1.7340306 | N29: 2.3
B30: IN SHEET 1 (E.G. SPECIFIED GENDER) + COPY-PASTED STAGE 1 MODEL] | M30: -1.7327954 | N30: 2.4
M31: -1.7315602 | N31: 2.5
M32: -1.7303456 | N32: 2.6
B33: Computed residual: | C33: ='Normative data'!D44-TMTB!C27 -> -4.4113913 | M33: -1.7291523 | N33: 2.7
B34: Std. Residual: | C34: =-(C33/SD_PERC_TMTB!I38) -> 11.881511 | I34: Residual Std.Error to be used: | J34: =SD_PERC_TMTB!I38 -> 0.371282 | M34: -1.7279591 | N34: 2.8
M35: -1.7128105 | N35: 2.9
M36: -1.6967518 | N36: 3
M37: -1.6849753 | N37: 3.1
M38: -1.6799601 | N38: 3.2
M39: -1.6749448 | N39: 3.3
M40: -1.6573481 | N40: 3.4
M41: -1.6372966 | N41: 3.5
M42: -1.6191495 | N42: 3.6
M43: -1.6057639 | N43: 3.7
...

Sheet SD_PERC_TMTB
A1: Determine SD(residual) to use; DO NOT MAKE CHANGES HERE | L1: Determine percentile
A3: Assuming homoscedasticity | G3: =SQRT(TMTB!J6) -> 0.371282
L4: =RAVLT_Learning!M5 -> Delta | M4: =RAVLT_Learning!N5 -> Percentile rank | O4: Abs diff delta | P4: Percentile
L5: =TMTB!M6 -> -2.719612 | M5: =TMTB!N6 -> 0 | O5: =ABS(L5-TMTB!$C$34) -> 14.601123 | P5: =M5 -> 0 | R5: Min abs delta | T5: =MIN(O5:O1006) -> 8.8803854
A6: Not assuming homoscedasticity, residual std.error per group: | L6: =TMTB!M7 -> -2.5059802 | M6: =TMTB!N7 -> 0.1 | O6: =ABS(L6-TMTB!$C$34) -> 14.387492 | P6: =M6 -> 0.1 | R6: Percentile | T6: =VLOOKUP(T5, O5:P1006, 2, ) -> 100
L7: =TMTB!M8 -> -2.2923485 | M7: =TMTB!N8 -> 0.2 | O7: =ABS(L7-TMTB!$C$34) -> 14.17386 | P7: =M7 -> 0.2
A8: Predicted score: | B8: =TMTB!C27 -> 4.4113913
L9: =TMTB!M9 -> -2.1481112 | M9: =TMTB!N9 -> 0.3 | O9: =ABS(L9-TMTB!$C$34) -> 14.029623 | P9: =M9 -> 0.3
B10: =RAVLT_Learning!J10 -> Residual variance | C10: =RAVLT_Learning!I10 -> Predicted test score | L10: =TMTB!M10 -> -2.0890399 | M10: =TMTB!N10 -> 0.4 | O10: =ABS(L10-TMTB!$C$34) -> 13.970551 | P10: =M10 -> 0.4
B11: =TMTA!J11 -> 0 | C11: =TMTA!I11 -> 0 | L11: =TMTB!M11 -> -2.0299687 | M11: =TMTB!N11 -> 0.5 | O11: =ABS(L11-TMTB!$C$34) -> 13.91148 | P11: =M11 -> 0.5
B12: =TMTA!J12 -> 0 | C12: =TMTA!I12 -> 0 | L12: =TMTB!M12 -> -1.9608566 | M12: =TMTB!N12 -> 0.6 | O12: =ABS(L12-TMTB!$C$34) -> 13.842368 | P12: =M12 -> 0.6
B13: =TMTA!J13 -> 0 | C13: =TMTA!I13 -> 0 | L13: =TMTB!M13 -> -1.8906036 | M13: =TMTB!N13 -> 0.7 | O13: =ABS(L13-TMTB!$C$34) -> 13.772115 | P13: =M13 -> 0.7
B14: =TMTA!J14 -> 0 | C14: =TMTA!I14 -> 0 | L14: =TMTB!M14 -> -1.843478 | M14: =TMTB!N14 -> 0.8 | O14: =ABS(L14-TMTB!$C$34) -> 13.724989 | P14: =M14 -> 0.8
B15: =TMTA!J15 -> 0 | C15: =TMTA!I15 -> 0 | L15: =TMTB!M15 -> -1.8398865 | M15: =TMTB!N15 -> 0.9 | O15: =ABS(L15-TMTB!$C$34) -> 13.721398 | P15: =M15 -> 0.9
B16: =TMTA!J16 -> 0 | C16: =TMTA!I16 -> 0 | L16: =TMTB!M16 -> -1.836295 | M16: =TMTB!N16 -> 1 | O16: =ABS(L16-TMTB!$C$34) -> 13.717806 | P16: =M16 -> 1
B17: =TMTA!J17 -> 0 | C17: =TMTA!I17 -> 0 | L17: =TMTB!M17 -> -1.832188 | M17: =TMTB!N17 -> 1.1 | O17: =ABS(L17-TMTB!$C$34) -> 13.713699 | P17: =M17 -> 1.1
B18: =TMTA!J18 -> 0 | C18: =TMTA!I18 -> 0 | L18: =TMTB!M18 -> -1.8279489 | M18: =TMTB!N18 -> 1.2 | O18: =ABS(L18-TMTB!$C$34) -> 13.70946 | P18: =M18 -> 1.2
B19: =TMTA!J19 -> 0 | C19: =TMTA!I19 -> 0 | L19: =TMTB!M19 -> -1.8242391 | M19: =TMTB!N19 -> 1.3 | O19: =ABS(L19-TMTB!$C$34) -> 13.705751 | P19: =M19 -> 1.3
B20: =TMTA!J20 -> 0 | C20: =TMTA!I20 -> 0 | E20: Residual variance | G20: {=INDEX(B11:B22,MATCH(MIN(ABS(C11:C22-B8)),ABS(C11:C22-B8),0))} -> 0 | L20: =TMTB!M20 -> -1.8221611 | M20: =TMTB!N20 -> 1.4 | O20: =ABS(L20-TMTB!$C$34) -> 13.703673 | P20: =M20 -> 1.4
B21: =TMTA!J21 -> 0 | C21: =TMTA!I21 -> 0 | E21: Residual std. Error | G21: =SQRT(G20) -> 0 | L21: =TMTB!M21 -> -1.8200831 | M21: =TMTB!N21 -> 1.5 | O21: =ABS(L21-TMTB!$C$34) -> 13.701595 | P21: =M21 -> 1.5
B22: =TMTA!J22 -> 0 | C22: =TMTA!I22 -> 0 | L22: =TMTB!M22 -> -1.8109601 | M22: =TMTB!N22 -> 1.6 | O22: =ABS(L22-TMTB!$C$34) -> 13.692471 | P22: =M22 -> 1.6
E23: Formula, see: | F23: https://www.excel-easy.com/examples/closest-match.html | L23: =TMTB!M23 -> -1.7987289 | M23: =TMTB!N23 -> 1.7 | O23: =ABS(L23-TMTB!$C$34) -> 13.68024 | P23: =M23 -> 1.7
L24: =TMTB!M24 -> -1.7878513 | M24: =TMTB!N24 -> 1.8 | O24: =ABS(L24-TMTB!$C$34) -> 13.669363 | P24: =M24 -> 1.8
A25: Not assuming homoscedasticity, variance function | L25: =TMTB!M25 -> -1.7850956 | M25: =TMTB!N25 -> 1.9 | O25: =ABS(L25-TMTB!$C$34) -> 13.666607 | P25: =M25 -> 1.9
L26: =TMTB!M26 -> -1.7823398 | M26: =TMTB!N26 -> 2 | O26: =ABS(L26-TMTB!$C$34) -> 13.663851 | P26: =M26 -> 2
A27: =RAVLT_Learning!I26 | B27: =RAVLT_Learning!J26 -> Estimate | C27: X | D27: Beta x X | L27: =TMTB!M27 -> -1.7702799 | M27: =TMTB!N27 -> 2.1 | O27: =ABS(L27-TMTB!$C$34) -> 13.651791 | P27: =M27 -> 2.1
A28: =TMTB!I27 -> 0 | B28: =TMTB!J27 -> 0 | C28: 1 | D28: =B28*C28 -> 0 | L28: =TMTB!M28 -> -1.7518034 | M28: =TMTB!N28 -> 2.2 | O28: =ABS(L28-TMTB!$C$34) -> 13.633315 | P28: =M28 -> 2.2
A29: =TMTB!I28 -> 0 | B29: =TMTB!J28 -> 0 | C29: =B8 -> 4.4113913 | D29: =B29*C29 -> 0 | L29: =TMTB!M29 -> -1.7340306 | M29: =TMTB!N29 -> 2.3 | O29: =ABS(L29-TMTB!$C$34) -> 13.615542 | P29: =M29 -> 2.3
A30: =TMTB!I29 -> 0 | B30: =TMTB!J29 -> 0 | C30: =B8^2 -> 19.460373 | D30: =B30*C30 -> 0 | L30: =TMTB!M30 -> -1.7327954 | M30: =TMTB!N30 -> 2.4 | O30: =ABS(L30-TMTB!$C$34) -> 13.614307 | P30: =M30 -> 2.4
A31: =TMTB!I30 -> 0 | B31: =TMTB!J30 -> 0 | C31: =B8^3 -> 85.847322 | D31: =B31*C31 -> 0 | L31: =TMTB!M31 -> -1.7315602 | M31: =TMTB!N31 -> 2.5 | O31: =ABS(L31-TMTB!$C$34) -> 13.613072 | P31: =M31 -> 2.5
A32: =TMTB!I31 -> 0 | B32: =TMTB!J31 -> 0 | C32: =B8^4 -> 378.70613 | D32: =B32*C32 -> 0 | L32: =TMTB!M32 -> -1.7303456 | M32: =TMTB!N32 -> 2.6 | O32: =ABS(L32-TMTB!$C$34) -> 13.611857 | P32: =M32 -> 2.6
A33: =TMTB!I32 -> 0 | B33: =TMTB!J32 -> 0 | C33: =B8^5 -> 1670.621 | D33: =B33*C33 -> 0 | L33: =TMTB!M33 -> -1.7291523 | M33: =TMTB!N33 -> 2.7 | O33: =ABS(L33-TMTB!$C$34) -> 13.610664 | P33: =M33 -> 2.7
G34: =SQRT(D35) -> 0 | L34: =TMTB!M34 -> -1.7279591 | M34: =TMTB!N34 -> 2.8 | O34: =ABS(L34-TMTB!$C$34) -> 13.60947 | P34: =M34 -> 2.8
B35: Predicted VARIANCE | D35: =SUM(D28:D34) -> 0 | L35: =TMTB!M35 -> -1.7128105 | M35: =TMTB!N35 -> 2.9 | O35: =ABS(L35-TMTB!$C$34) -> 13.594322 | P35: =M35 -> 2.9
L36: =TMTB!M36 -> -1.6967518 | M36: =TMTB!N36 -> 3 | O36: =ABS(L36-TMTB!$C$34) -> 13.578263 | P36: =M36 -> 3
A37: Checks | L37: =TMTB!M37 -> -1.6849753 | M37: =TMTB!N37 -> 3.1 | O37: =ABS(L37-TMTB!$C$34) -> 13.566487 | P37: =M37 -> 3.1
A38: Overall resid std error entered | D38: =IF(G3>0, 1, 0) -> 1 | G38: Res. Std error | I38: =IF(D41=1, G3+G21+G34, ) -> 0.371282 | L38: =TMTB!M38 -> -1.6799601 | M38: =TMTB!N38 -> 3.2 | O38: =ABS(L38-TMTB!$C$34) -> 13.561471 | P38: =M38 -> 3.2
A39: Resid std per group | D39: =IF(G21>0, 1, 0) -> 0 | I39: =IF(D41=1, " ", "ERROR!") | L39: =TMTB!M39 -> -1.6749448 | M39: =TMTB!N39 -> 3.3 | O39: =ABS(L39-TMTB!$C$34) -> 13.556456 | P39: =M39 -> 3.3
A40: Variance function | D40: =IF(G34>0, 1, 0) -> 0 | L40: =TMTB!M40 -> -1.6573481 | M40: =TMTB!N40 -> 3.4 | O40: =ABS(L40-TMTB!$C$34) -> 13.53886 | P40: =M40 -> 3.4
C41: Som | D41: =SUM(D38:D40) -> 1 | E41: (check should be 1 to be OK) | L41: =TMTB!M41 -> -1.6372966 | M41: =TMTB!N41 -> 3.5 | O41: =ABS(L41-TMTB!$C$34) -> 13.518808 | P41: =M41 -> 3.5
...

Sheet TMTA
B1: ONLY MAKE CHANGES IN THE GREY HIGHLIGHTED CELLS | I1: =SD_PERC_TMTA!A42
A3: 1 | B3: COPY-PASTE FINAL STAGE 1 MEAN PREDICTION FUNCTION HERE: | H3: 2 | I3: COPY-PASTE FINAL STAGE 1 VARIANCE PREDICTION FUNCTION HERE: | L3: 3 | M3: COPY-PASTE PERCENTILE RANKS DELTA HERE:
C5: Estimate | H5: A | I5: Assuming homoscedasticity | M5: Delta | N5: Percentile rank
B6: (Intercept) | C6: 4.1555589 | I6: Residual variance | J6: 0.11273746 | M6: -2.731755 | N6: 0
B7: age_log_100 | C7: 1.318228 | M7: -2.6745912 | N7: 0.1
M8: -2.6174274 | N8: 0.2
H9: B | I9: Not assuming homoscedasticity, prediction-specific residual variances: | M9: -2.5589968 | N9: 0.3
I10: Predicted test score | J10: Residual variance | M10: -2.4990114 | N10: 0.4
M11: -2.439026 | N11: 0.5
M12: -2.3878469 | N12: 0.6
M13: -2.3376685 | N13: 0.7
M14: -2.2820305 | N14: 0.8
M15: -2.2161153 | N15: 0.9
M16: -2.1502001 | N16: 1
M17: -2.1049277 | N17: 1.1
M18: -2.0649484 | N18: 1.2
M19: -2.032953 | N19: 1.3
M20: -2.0255744 | N20: 1.4
M21: -2.0181958 | N21: 1.5
M22: -1.9646685 | N22: 1.6
... M24: -1.82745 | N24: 1.8
H25: C | I25: Not assuming homoscedasticity, continuous variance prediction function: | M25: -1.82745 | N25: 1.9
C26: Log scale | D26: Seconds | J26: Estimate | M26: -1.82745 | N26: 2
A27: 4 | B27: Predicted test score: | C27: =C6+(C7*(LN('Normative data'!C6 / 100))) -> 3.4821742 | D27: =EXP(C27) -> 32.530374 | M27: -1.8243837 | N27: 2.1
B28: [SPECIFY THE APPROPRIATE FORMULA IN CELL B27 TO COMPUTE | M28: -1.8192026 | N28: 2.2
B29: THE PREDICTED TEST SCORE BASED ON THE INPUT PROVIDED | M29: -1.8138946 | N29: 2.3
B30: IN SHEET 1 (E.G. SPECIFIED GENDER) + COPY-PASTED STAGE 1 MODEL] | M30: -1.805603 | N30: 2.4
M31: -1.7973114 | N31: 2.5
M32: -1.7923324 | N32: 2.6
B33: Computed residual: | C33: ='Normative data'!D43-TMTA!C27 -> -3.4821742 | M33: -1.790804 | N33: 2.7
B34: Std. Residual: | C34: =-(C33/SD_PERC_TMTA!I38) -> 10.370898 | I34: Residual Std.Error to be used: | J34: =SD_PERC_TMTA!I38 -> 0.335764 | M34: -1.7892756 | N34: 2.8
M35: -1.7864761 | N35: 2.9
M36: -1.7835937 | N36: 3
M37: -1.7800471 | N37: 3.1
M38: -1.7754517 | N38: 3.2
M39: -1.7708563 | N39: 3.3
M40: -1.7677792 | N40: 3.4
M41: -1.7649983 | N41: 3.5
M42: -1.7612678 | N42: 3.6
M43: -1.7551632 | N43: 3.7
...

Sheet SD_PERC_TMTA
A1: Determine SD(residual) to use; DO NOT MAKE CHANGES HERE | L1: Determine percentile
A3: Assuming homoscedasticity | G3: =SQRT(TMTA!J6) -> 0.335764
L4: =RAVLT_Learning!M5 -> Delta | M4: =RAVLT_Learning!N5 -> Percentile rank | O4: Abs diff delta | P4: Percentile
L5: =TMTA!M6 -> -2.731755 | M5: =TMTA!N6 -> 0 | O5: =ABS(L5-TMTA!$C$34) -> 13.102653 | P5: =M5 -> 0 | R5: Min abs delta | T5: =MIN(O5:O1006) -> 7.0681021
A6: Not assuming homoscedasticity, residual std.error per group: | L6: =TMTA!M7 -> -2.6745912 | M6: =TMTA!N7 -> 0.1 | O6: =ABS(L6-TMTA!$C$34) -> 13.045489 | P6: =M6 -> 0.1 | R6: Percentile | T6: =VLOOKUP(T5, O5:P1006, 2, ) -> 100
L7: =TMTA!M8 -> -2.6174274 | M7: =TMTA!N8 -> 0.2 | O7: =ABS(L7-TMTA!$C$34) -> 12.988326 | P7: =M7 -> 0.2
A8: Predicted score: | B8: =TMTA!C27 -> 3.4821742
L9: =TMTA!M9 -> -2.5589968 | M9: =TMTA!N9 -> 0.3 | O9: =ABS(L9-TMTA!$C$34) -> 12.929895 | P9: =M9 -> 0.3
B10: =RAVLT_Learning!J10 -> Residual variance | C10: =RAVLT_Learning!I10 -> Predicted test score | L10: =TMTA!M10 -> -2.4990114 | M10: =TMTA!N10 -> 0.4 | O10: =ABS(L10-TMTA!$C$34) -> 12.869909 | P10: =M10 -> 0.4
B11: =TMTA!J11 -> 0 | C11: =TMTA!I11 -> 0 | L11: =TMTA!M11 -> -2.439026 | M11: =TMTA!N11 -> 0.5 | O11: =ABS(L11-TMTA!$C$34) -> 12.809924 | P11: =M11 -> 0.5
B12: =TMTA!J12 -> 0 | C12: =TMTA!I12 -> 0 | L12: =TMTA!M12 -> -2.3878469 | M12: =TMTA!N12 -> 0.6 | O12: =ABS(L12-TMTA!$C$34) -> 12.758745 | P12: =M12 -> 0.6
B13: =TMTA!J13 -> 0 | C13: =TMTA!I13 -> 0 | L13: =TMTA!M13 -> -2.3376685 | M13: =TMTA!N13 -> 0.7 | O13: =ABS(L13-TMTA!$C$34) -> 12.708567 | P13: =M13 -> 0.7
B14: =TMTA!J14 -> 0 | C14: =TMTA!I14 -> 0 | L14: =TMTA!M14 -> -2.2820305 | M14: =TMTA!N14 -> 0.8 | O14: =ABS(L14-TMTA!$C$34) -> 12.652929 | P14: =M14 -> 0.8
B15: =TMTA!J15 -> 0 | C15: =TMTA!I15 -> 0 | L15: =TMTA!M15 -> -2.2161153 | M15: =TMTA!N15 -> 0.9 | O15: =ABS(L15-TMTA!$C$34) -> 12.587013 | P15: =M15 -> 0.9
B16: =TMTA!J16 -> 0 | C16: =TMTA!I16 -> 0 | L16: =TMTA!M16 -> -2.1502001 | M16: =TMTA!N16 -> 1 | O16: =ABS(L16-TMTA!$C$34) -> 12.521098 | P16: =M16 -> 1
B17: =TMTA!J17 -> 0 | C17: =TMTA!I17 -> 0 | L17: =TMTA!M17 -> -2.1049277 | M17: =TMTA!N17 -> 1.1 | O17: =ABS(L17-TMTA!$C$34) -> 12.475826 | P17: =M17 -> 1.1
B18: =TMTA!J18 -> 0 | C18: =TMTA!I18 -> 0 | L18: =TMTA!M18 -> -2.0649484 | M18: =TMTA!N18 -> 1.2 | O18: =ABS(L18-TMTA!$C$34) -> 12.435847 | P18: =M18 -> 1.2
B19: =TMTA!J19 -> 0 | C19: =TMTA!I19 -> 0 | L19: =TMTA!M19 -> -2.032953 | M19: =TMTA!N19 -> 1.3 | O19: =ABS(L19-TMTA!$C$34) -> 12.403851 | P19: =M19 -> 1.3
B20: =TMTA!J20 -> 0 | C20: =TMTA!I20 -> 0 | E20: Residual variance | G20: {=INDEX(B11:B22,MATCH(MIN(ABS(C11:C22-B8)),ABS(C11:C22-B8),0))} -> 0 | L20: =TMTA!M20 -> -2.0255744 | M20: =TMTA!N20 -> 1.4 | O20: =ABS(L20-TMTA!$C$34) -> 12.396472 | P20: =M20 -> 1.4
B21: =TMTA!J21 -> 0 | C21: =TMTA!I21 -> 0 | E21: Residual std. Error | G21: =SQRT(G20) -> 0 | L21: =TMTA!M21 -> -2.0181958 | M21: =TMTA!N21 -> 1.5 | O21: =ABS(L21-TMTA!$C$34) -> 12.389094 | P21: =M21 -> 1.5
B22: =TMTA!J22 -> 0 | C22: =TMTA!I22 -> 0 | L22: =TMTA!M22 -> -1.9646685 | M22: =TMTA!N22 -> 1.6 | O22: =ABS(L22-TMTA!$C$34) -> 12.335567 | P22: =M22 -> 1.6
E23: Formula, see: | F23: https://www.excel-easy.com/examples/closest-match.html | L23: =TMTA!M23 -> -1.8907816 | M23: =TMTA!N23 -> 1.7 | O23: =ABS(L23-TMTA!$C$34) -> 12.26168 | P23: =M23 -> 1.7
L24: =TMTA!M24 -> -1.82745 | M24: =TMTA!N24 -> 1.8 | O24: =ABS(L24-TMTA!$C$34) -> 12.198348 | P24: =M24 -> 1.8
A25: Not assuming homoscedasticity, variance function | L25: =TMTA!M25 -> -1.82745 | M25: =TMTA!N25 -> 1.9 | O25: =ABS(L25-TMTA!$C$34) -> 12.198348 | P25: =M25 -> 1.9
L26: =TMTA!M26 -> -1.82745 | M26: =TMTA!N26 -> 2 | O26: =ABS(L26-TMTA!$C$34) -> 12.198348 | P26: =M26 -> 2
A27: =RAVLT_Learning!I26 | B27: =RAVLT_Learning!J26 -> Estimate | C27: X | D27: Beta x X | L27: =TMTA!M27 -> -1.8243837 | M27: =TMTA!N27 -> 2.1 | O27: =ABS(L27-TMTA!$C$34) -> 12.195282 | P27: =M27 -> 2.1
A28: =TMTA!I27 -> 0 | B28: =TMTA!J27 -> 0 | C28: 1 | D28: =B28*C28 -> 0 | L28: =TMTA!M28 -> -1.8192026 | M28: =TMTA!N28 -> 2.2 | O28: =ABS(L28-TMTA!$C$34) -> 12.190101 | P28: =M28 -> 2.2
A29: =TMTA!I28 -> 0 | B29: =TMTA!J28 -> 0 | C29: =B8 -> 3.4821742 | D29: =B29*C29 -> 0 | L29: =TMTA!M29 -> -1.8138946 | M29: =TMTA!N29 -> 2.3 | O29: =ABS(L29-TMTA!$C$34) -> 12.184793 | P29: =M29 -> 2.3
A30: =TMTA!I29 -> 0 | B30: =TMTA!J29 -> 0 | C30: =B8^2 -> 12.125537 | D30: =B30*C30 -> 0 | L30: =TMTA!M30 -> -1.805603 | M30: =TMTA!N30 -> 2.4 | O30: =ABS(L30-TMTA!$C$34) -> 12.176501 | P30: =M30 -> 2.4
A31: =TMTA!I30 -> 0 | B31: =TMTA!J30 -> 0 | C31: =B8^3 -> 42.223234 | D31: =B31*C31 -> 0 | L31: =TMTA!M31 -> -1.7973114 | M31: =TMTA!N31 -> 2.5 | O31: =ABS(L31-TMTA!$C$34) -> 12.16821 | P31: =M31 -> 2.5
A32: =TMTA!I31 -> 0 | B32: =TMTA!J31 -> 0 | C32: =B8^4 -> 147.02866 | D32: =B32*C32 -> 0 | L32: =TMTA!M32 -> -1.7923324 | M32: =TMTA!N32 -> 2.6 | O32: =ABS(L32-TMTA!$C$34) -> 12.163231 | P32: =M32 -> 2.6
A33: =TMTA!I32 -> 0 | B33: =TMTA!J32 -> 0 | C33: =B8^5 -> 511.9794 | D33: =B33*C33 -> 0 | L33: =TMTA!M33 -> -1.790804 | M33: =TMTA!N33 -> 2.7 | O33: =ABS(L33-TMTA!$C$34) -> 12.161702 | P33: =M33 -> 2.7
G34: =SQRT(D35) -> 0 | L34: =TMTA!M34 -> -1.7892756 | M34: =TMTA!N34 -> 2.8 | O34: =ABS(L34-TMTA!$C$34) -> 12.160174 | P34: =M34 -> 2.8
B35: Predicted VARIANCE | D35: =SUM(D28:D34) -> 0 | L35: =TMTA!M35 -> -1.7864761 | M35: =TMTA!N35 -> 2.9 | O35: =ABS(L35-TMTA!$C$34) -> 12.157374 | P35: =M35 -> 2.9
L36: =TMTA!M36 -> -1.7835937 | M36: =TMTA!N36 -> 3 | O36: =ABS(L36-TMTA!$C$34) -> 12.154492 | P36: =M36 -> 3
A37: Checks | L37: =TMTA!M37 -> -1.7800471 | M37: =TMTA!N37 -> 3.1 | O37: =ABS(L37-TMTA!$C$34) -> 12.150945 | P37: =M37 -> 3.1
A38: Overall resid std error entered | D38: =IF(G3>0, 1, 0) -> 1 | G38: Res. Std error | I38: =IF(D41=1, G3+G21+G34, ) -> 0.335764 | L38: =TMTA!M38 -> -1.7754517 | M38: =TMTA!N38 -> 3.2 | O38: =ABS(L38-TMTA!$C$34) -> 12.14635 | P38: =M38 -> 3.2
A39: Resid std per group | D39: =IF(G21>0, 1, 0) -> 0 | I39: =IF(D41=1, " ", "ERROR!") | L39: =TMTA!M39 -> -1.7708563 | M39: =TMTA!N39 -> 3.3 | O39: =ABS(L39-TMTA!$C$34) -> 12.141754 | P39: =M39 -> 3.3
A40: Variance function | D40: =IF(G34>0, 1, 0) -> 0 | L40: =TMTA!M40 -> -1.7677792 | M40: =TMTA!N40 -> 3.4 | O40: =ABS(L40-TMTA!$C$34) -> 12.138677 | P40: =M40 -> 3.4
C41: Som | D41: =SUM(D38:D40) -> 1 | E41: (check should be 1 to be OK) | L41: =TMTA!M41 -> -1.7649983 | M41: =TMTA!N41 -> 3.5 | O41: =ABS(L41-TMTA!$C$34) -> 12.135896 | P41: =M41 -> 3.5
...

Sheet DigInv
B1: ONLY MAKE CHANGES IN THE GREY HIGHLIGHTED CELLS | I1: =SD_PERC_DigDir!A42
A3: 1 | B3: COPY-PASTE FINAL STAGE 1 MEAN PREDICTION FUNCTION HERE: | H3: 2 | I3: COPY-PASTE FINAL STAGE 1 VARIANCE PREDICTION FUNCTION HERE: | L3: 3 | M3: COPY-PASTE PERCENTILE RANKS DELTA HERE:
C5: Estimate | H5: A | I5: Assuming homoscedasticity | M5: Delta | N5: Percentile rank
B6: (Intercept) | C6: 3.6465854 | I6: Residual variance | M6: -1.622793 | N6: 0
B7: years_education | C7: 0.052568812 | M7: -1.622793 | N7: 0.1
M8: -1.622793 | N8: 0.2
H9: B | I9: Not assuming homoscedasticity, prediction-specific residual variances: | M9: -1.622793 | N9: 0.3
I10: Predicted test score | J10: Residual variance | M10: -1.622793 | N10: 0.4
M11: -1.622793 | N11: 0.5
M12: -1.622793 | N12: 0.6
M13: -1.622793 | N13: 0.7
M14: -1.622793 | N14: 0.8
M15: -1.622793 | N15: 0.9
M16: -1.622793 | N16: 1
M17: -1.622793 | N17: 1.1
M18: -1.622793 | N18: 1.2
M19: -1.622793 | N19: 1.3
M20: -1.622793 | N20: 1.4
M21: -1.622793 | N21: 1.5
M22: -1.622793 | N22: 1.6
... M24: -1.622793 | N24: 1.8
H25: C | I25: Not assuming homoscedasticity, continuous variance prediction function: | M25: -1.622793 | N25: 1.9
J26: Estimate | M26: -1.622793 | N26: 2
A27: 4 | B27: Predicted test score: | C27: =$C$6 + $C$7*('Normative data'!C8) -> 4.2774111 | I27: (Intercept) | J27: 20.969942 | M27: -1.6224668 | N27: 2.1
B28: [SPECIFY THE APPROPRIATE FORMULA IN CELL B27 TO COMPUTE | I28: Pred.Y | J28: -10.881346 | M28: -1.6219157 | N28: 2.2
B29: THE PREDICTED TEST SCORE BASED ON THE INPUT PROVIDED | I29: Pred.Y.2 | J29: 1.615519 | M29: -1.621387 | N29: 2.3
B30: IN SHEET 1 (E.G. SPECIFIED GENDER) + COPY-PASTED STAGE 1 MODEL] | I30: Pred.Y.3 | J30: -0.042387637 | M30: -1.621387 | N30: 2.4
M31: -1.621387 | N31: 2.5
M32: -1.621387 | N32: 2.6
B33: Computed residual: | C33: ='Normative data'!C15-DigInv!C27 -> -3.2774111 | M33: -1.621387 | N33: 2.7
B34: Std. Residual: | C34: =C33/SD_PERC_DigInv!I38 -> -4.0141884 | I34: Residual Std.Error to be used: | J34: =SD_PERC_DigInv!I38 -> 0.81645672 | M34: -1.621387 | N34: 2.8
M35: -1.621387 | N35: 2.9
M36: -1.621387 | N36: 3
M37: -1.621387 | N37: 3.1
M38: -1.621387 | N38: 3.2
M39: -1.621387 | N39: 3.3
M40: -1.621387 | N40: 3.4
M41: -1.621387 | N41: 3.5
M42: -1.621387 | N42: 3.6
M43: -1.621387 | N43: 3.7
...

Sheet DigDir
B1: ONLY MAKE CHANGES IN THE GREY HIGHLIGHTED CELLS | I1: =SD_PERC_DigDir!A42
A3: 1 | B3: COPY-PASTE FINAL STAGE 1 MEAN PREDICTION FUNCTION HERE: | H3: 2 | I3: COPY-PASTE FINAL STAGE 1 VARIANCE PREDICTION FUNCTION HERE: | L3: 3 | M3: COPY-PASTE PERCENTILE RANKS DELTA HERE:
C5: Estimate | H5: A | I5: Assuming homoscedasticity | M5: Delta | N5: Percentile rank
B6: (Intercept) | C6: 5.1879334 | I6: Residual variance | J6: 1.0649002 | M6: -2.315013 | N6: 0
B7: years_education | C7: 0.060051098 | M7: -2.315013 | N7: 0.1
M8: -2.315013 | N8: 0.2
H9: B | I9: Not assuming homoscedasticity, prediction-specific residual variances: | M9: -2.2945294 | N9: 0.3
I10: Predicted test score | J10: Residual variance | M10: -2.2489069 | N10: 0.4
M11: -2.2032844 | N11: 0.5
M12: -2.198629 | N12: 0.6
M13: -2.198629 | N13: 0.7
M14: -2.198629 | N14: 0.8
M15: -2.198629 | N15: 0.9
M16: -2.198629 | N16: 1
M17: -2.1804728 | N17: 1.1
M18: -2.1576611 | N18: 1.2
M19: -2.140436 | N19: 1.3
M20: -2.140436 | N20: 1.4
M21: -2.140436 | N21: 1.5
M22: -2.1246078 | N22: 1.6
... M24: -2.082244 | N24: 1.8
H25: C | I25: Not assuming homoscedasticity, continuous variance prediction function: | M25: -2.082244 | N25: 1.9
J26: Estimate | M26: -2.082244 | N26: 2
A27: 4 | B27: Predicted test score: | C27: =C6+(C7*('Normative data'!C8)) -> 5.9085465 | M27: -2.0687435 | N27: 2.1
B28: [SPECIFY THE APPROPRIATE FORMULA IN CELL B27 TO COMPUTE | M28: -2.0459322 | N28: 2.2
B29: THE PREDICTED TEST SCORE BASED ON THE INPUT PROVIDED | M29: -2.024052 | N29: 2.3
B30: IN SHEET 1 (E.G. SPECIFIED GENDER) + COPY-PASTED STAGE 1 MODEL] | M30: -2.024052 | N30: 2.4
M31: -2.024052 | N31: 2.5
M32: -2.024052 | N32: 2.6
B33: Computed residual: | C33: ='Normative data'!C14-DigDir!C27 -> -4.9085465 | M33: -2.024052 | N33: 2.7
B34: Std. Residual: | C34: =C33/SD_PERC_DigDir!I38 -> -4.7566201 | I34: Residual Std.Error to be used: | J34: =SD_PERC_DigDir!I38 -> 1.03194 | M34: -2.024052 | N34: 2.8
M35: -2.002637 | N35: 2.9
M36: -1.9798253 | N36: 3
M37: -1.9570138 | N37: 3.1
M38: -1.9342026 | N38: 3.2
M39: -1.9113913 | N39: 3.3
M40: -1.88858 | N40: 3.4
M41: -1.8657688 | N41: 3.5
M42: -1.849475 | N42: 3.6
M43: -1.849475 | N43: 3.7
...

Sheet SD_PERC_DigInv
A1: Determine SD(residual) to use; DO NOT MAKE CHANGES HERE | L1: Determine percentile
A3: Assuming homoscedasticity | G3: =SQRT(DigInv!J6) -> 0
L4: =RAVLT_Learning!M5 -> Delta | M4: =RAVLT_Learning!N5 -> Percentile rank | O4: Abs diff delta | P4: Percentile
L5: =DigInv!M6 -> -1.622793 | M5: =DigDir!N6 -> 0 | O5: =ABS(L5-DigInv!$C$34) -> 2.3913954 | P5: =M5 -> 0 | R5: Min abs delta | T5: =MIN(O5:O1006) -> 2.3913954
A6: Not assuming homoscedasticity, residual std.error per group: | L6: =DigInv!M7 -> -1.622793 | M6: =DigDir!N7 -> 0.1 | O6: =ABS(L6-DigInv!$C$34) -> 2.3913954 | P6: =M6 -> 0.1 | R6: Percentile | T6: =VLOOKUP(T5, O5:P1006, 2, ) -> 0
L7: =DigInv!M8 -> -1.622793 | M7: =DigDir!N8 -> 0.2 | O7: =ABS(L7-DigInv!$C$34) -> 2.3913954 | P7: =M7 -> 0.2
A8: Predicted score: | B8: =DigInv!C27 -> 4.2774111
L9: =DigInv!M9 -> -1.622793 | M9: =DigDir!N9 -> 0.3 | O9: =ABS(L9-DigInv!$C$34) -> 2.3913954 | P9: =M9 -> 0.3
B10: =RAVLT_Learning!J10 -> Residual variance | C10: =RAVLT_Learning!I10 -> Predicted test score | L10: =DigInv!M10 -> -1.622793 | M10: =DigDir!N10 -> 0.4 | O10: =ABS(L10-DigInv!$C$34) -> 2.3913954 | P10: =M10 -> 0.4
B11: =DigInv!J11 -> 0 | C11: =DigInv!I11 -> 0 | L11: =DigInv!M11 -> -1.622793 | M11: =DigDir!N11 -> 0.5 | O11: =ABS(L11-DigInv!$C$34) -> 2.3913954 | P11: =M11 -> 0.5
B12: =DigInv!J12 -> 0 | C12: =DigInv!I12 -> 0 | L12: =DigInv!M12 -> -1.622793 | M12: =DigDir!N12 -> 0.6 | O12: =ABS(L12-DigInv!$C$34) -> 2.3913954 | P12: =M12 -> 0.6
B13: =DigInv!J13 -> 0 | C13: =DigInv!I13 -> 0 | L13: =DigInv!M13 -> -1.622793 | M13: =DigDir!N13 -> 0.7 | O13: =ABS(L13-DigInv!$C$34) -> 2.3913954 | P13: =M13 -> 0.7
B14: =DigInv!J14 -> 0 | C14: =DigInv!I14 -> 0 | L14: =DigInv!M14 -> -1.622793 | M14: =DigDir!N14 -> 0.8 | O14: =ABS(L14-DigInv!$C$34) -> 2.3913954 | P14: =M14 -> 0.8
B15: =DigInv!J15 -> 0 | C15: =DigInv!I15 -> 0 | L15: =DigInv!M15 -> -1.622793 | M15: =DigDir!N15 -> 0.9 | O15: =ABS(L15-DigInv!$C$34) -> 2.3913954 | P15: =M15 -> 0.9
B16: =DigInv!J16 -> 0 | C16: =DigInv!I16 -> 0 | L16: =DigInv!M16 -> -1.622793 | M16: =DigDir!N16 -> 1 | O16: =ABS(L16-DigInv!$C$34) -> 2.3913954 | P16: =M16 -> 1
B17: =DigInv!J17 -> 0 | C17: =DigInv!I17 -> 0 | L17: =DigInv!M17 -> -1.622793 | M17: =DigDir!N17 -> 1.1 | O17: =ABS(L17-DigInv!$C$34) -> 2.3913954 | P17: =M17 -> 1.1
B18: =DigInv!J18 -> 0 | C18: =DigInv!I18 -> 0 | L18: =DigInv!M18 -> -1.622793 | M18: =DigDir!N18 -> 1.2 | O18: =ABS(L18-DigInv!$C$34) -> 2.3913954 | P18: =M18 -> 1.2
B19: =DigInv!J19 -> 0 | C19: =DigInv!I19 -> 0 | L19: =DigInv!M19 -> -1.622793 | M19: =DigDir!N19 -> 1.3 | O19: =ABS(L19-DigInv!$C$34) -> 2.3913954 | P19: =M19 -> 1.3
B20: =DigInv!J20 -> 0 | C20: =DigInv!I20 -> 0 | E20: Residual variance | G20: {=INDEX(B11:B22,MATCH(MIN(ABS(C11:C22-B8)),ABS(C11:C22-B8),0))} -> 0 | L20: =DigInv!M20 -> -1.622793 | M20: =DigDir!N20 -> 1.4 | O20: =ABS(L20-DigInv!$C$34) -> 2.3913954 | P20: =M20 -> 1.4
B21: =DigInv!J21 -> 0 | C21: =DigInv!I21 -> 0 | E21: Residual std. Error | G21: =SQRT(G20) -> 0 | L21: =DigInv!M21 -> -1.622793 | M21: =DigDir!N21 -> 1.5 | O21: =ABS(L21-DigInv!$C$34) -> 2.3913954 | P21: =M21 -> 1.5
B22: =DigInv!J22 -> 0 | C22: =DigInv!I22 -> 0 | L22: =DigInv!M22 -> -1.622793 | M22: =DigDir!N22 -> 1.6 | O22: =ABS(L22-DigInv!$C$34) -> 2.3913954 | P22: =M22 -> 1.6
E23: Formula, see: | F23: https://www.excel-easy.com/examples/closest-match.html | L23: =DigInv!M23 -> -1.622793 | M23: =DigDir!N23 -> 1.7 | O23: =ABS(L23-DigInv!$C$34) -> 2.3913954 | P23: =M23 -> 1.7
L24: =DigInv!M24 -> -1.622793 | M24: =DigDir!N24 -> 1.8 | O24: =ABS(L24-DigInv!$C$34) -> 2.3913954 | P24: =M24 -> 1.8
A25: Not assuming homoscedasticity, variance function | L25: =DigInv!M25 -> -1.622793 | M25: =DigDir!N25 -> 1.9 | O25: =ABS(L25-DigInv!$C$34) -> 2.3913954 | P25: =M25 -> 1.9
L26: =DigInv!M26 -> -1.622793 | M26: =DigDir!N26 -> 2 | O26: =ABS(L26-DigInv!$C$34) -> 2.3913954 | P26: =M26 -> 2
A27: =RAVLT_Learning!I26 | B27: =RAVLT_Learning!J26 -> Estimate | C27: X | D27: Beta x X | L27: =DigInv!M27 -> -1.6224668 | M27: =DigDir!N27 -> 2.1 | O27: =ABS(L27-DigInv!$C$34) -> 2.3917216 | P27: =M27 -> 2.1
A28: =DigInv!I27 -> (Intercept) | B28: =DigInv!J27 -> 20.969942 | C28: 1 | D28: =B28*C28 -> 20.969942 | L28: =DigInv!M28 -> -1.6219157 | M28: =DigDir!N28 -> 2.2 | O28: =ABS(L28-DigInv!$C$34) -> 2.3922728 | P28: =M28 -> 2.2
A29: =DigInv!I28 -> Pred.Y | B29: =DigInv!J28 -> -10.881346 | C29: =B8 -> 4.2774111 | D29: =B29*C29 -> -46.543992 | L29: =DigInv!M29 -> -1.621387 | M29: =DigDir!N29 -> 2.3 | O29: =ABS(L29-DigInv!$C$34) -> 2.3928014 | P29: =M29 -> 2.3
A30: =DigInv!I29 -> Pred.Y.2 | B30: =DigInv!J29 -> 1.615519 | C30: =B8^2 -> 18.296246 | D30: =B30*C30 -> 29.557932 | L30: =DigInv!M30 -> -1.621387 | M30: =DigDir!N30 -> 2.4 | O30: =ABS(L30-DigInv!$C$34) -> 2.3928014 | P30: =M30 -> 2.4
A31: =DigInv!I30 -> Pred.Y.3 | B31: =DigInv!J30 -> -0.042387637 | C31: =B8^3 -> 78.260565 | D31: =B31*C31 -> -3.3172804 | L31: =DigInv!M31 -> -1.621387 | M31: =DigDir!N31 -> 2.5 | O31: =ABS(L31-DigInv!$C$34) -> 2.3928014 | P31: =M31 -> 2.5
A32: =DigInv!I31 -> 0 | B32: =DigInv!J31 -> 0 | C32: =B8^4 -> 334.75261 | D32: =B32*C32 -> 0 | L32: =DigInv!M32 -> -1.621387 | M32: =DigDir!N32 -> 2.6 | O32: =ABS(L32-DigInv!$C$34) -> 2.3928014 | P32: =M32 -> 2.6
A33: =DigInv!I32 -> 0 | B33: =DigInv!J32 -> 0 | C33: =B8^5 -> 1431.8745 | D33: =B33*C33 -> 0 | L33: =DigInv!M33 -> -1.621387 | M33: =DigDir!N33 -> 2.7 | O33: =ABS(L33-DigInv!$C$34) -> 2.3928014 | P33: =M33 -> 2.7
G34: =SQRT(D35) -> 0.81645672 | L34: =DigInv!M34 -> -1.621387 | M34: =DigDir!N34 -> 2.8 | O34: =ABS(L34-DigInv!$C$34) -> 2.3928014 | P34: =M34 -> 2.8
B35: Predicted VARIANCE | D35: =SUM(D28:D34) -> 0.66660157 | L35: =DigInv!M35 -> -1.621387 | M35: =DigDir!N35 -> 2.9 | O35: =ABS(L35-DigInv!$C$34) -> 2.3928014 | P35: =M35 -> 2.9
L36: =DigInv!M36 -> -1.621387 | M36: =DigDir!N36 -> 3 | O36: =ABS(L36-DigInv!$C$34) -> 2.3928014 | P36: =M36 -> 3
A37: Checks | L37: =DigInv!M37 -> -1.621387 | M37: =DigDir!N37 -> 3.1 | O37: =ABS(L37-DigInv!$C$34) -> 2.3928014 | P37: =M37 -> 3.1
A38: Overall resid std error entered | D38: =IF(G3>0, 1, 0) -> 0 | G38: Res. Std error | I38: =IF(D41=1, G3+G21+G34, ) -> 0.81645672 | L38: =DigInv!M38 -> -1.621387 | M38: =DigDir!N38 -> 3.2 | O38: =ABS(L38-DigInv!$C$34) -> 2.3928014 | P38: =M38 -> 3.2
A39: Resid std per group | D39: =IF(G21>0, 1, 0) -> 0 | I39: =IF(D41=1, " ", "ERROR!") | L39: =DigInv!M39 -> -1.621387 | M39: =DigDir!N39 -> 3.3 | O39: =ABS(L39-DigInv!$C$34) -> 2.3928014 | P39: =M39 -> 3.3
A40: Variance function | D40: =IF(G34>0, 1, 0) -> 1 | L40: =DigInv!M40 -> -1.621387 | M40: =DigDir!N40 -> 3.4 | O40: =ABS(L40-DigInv!$C$34) -> 2.3928014 | P40: =M40 -> 3.4
C41: Som | D41: =SUM(D38:D40) -> 1 | E41: (check should be 1 to be OK) | L41: =DigInv!M41 -> -1.621387 | M41: =DigDir!N41 -> 3.5 | O41: =ABS(L41-DigInv!$C$34) -> 2.3928014 | P41: =M41 -> 3.5
...

Sheet SD_PERC_DigDir
A1: Determine SD(residual) to use; DO NOT MAKE CHANGES HERE | L1: Determine percentile
A3: Assuming homoscedasticity | G3: =SQRT(DigDir!J6) -> 1.03194
L4: =RAVLT_Learning!M5 -> Delta | M4: =RAVLT_Learning!N5 -> Percentile rank | O4: Abs diff delta | P4: Percentile
L5: =DigDir!M6 -> -2.315013 | M5: =DigDir!N6 -> 0 | O5: =ABS(L5-DigDir!$C$34) -> 2.4416071 | P5: =M5 -> 0 | R5: Min abs delta | T5: =MIN(O5:O1006) -> 2.4416071
A6: Not assuming homoscedasticity, residual std.error per group: | L6: =DigDir!M7 -> -2.315013 | M6: =DigDir!N7 -> 0.1 | O6: =ABS(L6-DigDir!$C$34) -> 2.4416071 | P6: =M6 -> 0.1 | R6: Percentile | T6: =VLOOKUP(T5, O5:P1006, 2, ) -> 0
L7: =DigDir!M8 -> -2.315013 | M7: =DigDir!N8 -> 0.2 | O7: =ABS(L7-DigDir!$C$34) -> 2.4416071 | P7: =M7 -> 0.2
A8: Predicted score: | B8: =DigDir!C27 -> 5.9085465
L9: =DigDir!M9 -> -2.2945294 | M9: =DigDir!N9 -> 0.3 | O9: =ABS(L9-DigDir!$C$34) -> 2.4620907 | P9: =M9 -> 0.3
B10: =RAVLT_Learning!J10 -> Residual variance | C10: =RAVLT_Learning!I10 -> Predicted test score | L10: =DigDir!M10 -> -2.2489069 | M10: =DigDir!N10 -> 0.4 | O10: =ABS(L10-DigDir!$C$34) -> 2.5077132 | P10: =M10 -> 0.4
B11: =DigDir!J11 -> 0 | C11: =DigDir!I11 -> 0 | L11: =DigDir!M11 -> -2.2032844 | M11: =DigDir!N11 -> 0.5 | O11: =ABS(L11-DigDir!$C$34) -> 2.5533357 | P11: =M11 -> 0.5
B12: =DigDir!J12 -> 0 | C12: =DigDir!I12 -> 0 | L12: =DigDir!M12 -> -2.198629 | M12: =DigDir!N12 -> 0.6 | O12: =ABS(L12-DigDir!$C$34) -> 2.5579911 | P12: =M12 -> 0.6
B13: =DigDir!J13 -> 0 | C13: =DigDir!I13 -> 0 | L13: =DigDir!M13 -> -2.198629 | M13: =DigDir!N13 -> 0.7 | O13: =ABS(L13-DigDir!$C$34) -> 2.5579911 | P13: =M13 -> 0.7
B14: =DigDir!J14 -> 0 | C14: =DigDir!I14 -> 0 | L14: =DigDir!M14 -> -2.198629 | M14: =DigDir!N14 -> 0.8 | O14: =ABS(L14-DigDir!$C$34) -> 2.5579911 | P14: =M14 -> 0.8
B15: =DigDir!J15 -> 0 | C15: =DigDir!I15 -> 0 | L15: =DigDir!M15 -> -2.198629 | M15: =DigDir!N15 -> 0.9 | O15: =ABS(L15-DigDir!$C$34) -> 2.5579911 | P15: =M15 -> 0.9
B16: =DigDir!J16 -> 0 | C16: =DigDir!I16 -> 0 | L16: =DigDir!M16 -> -2.198629 | M16: =DigDir!N16 -> 1 | O16: =ABS(L16-DigDir!$C$34) -> 2.5579911 | P16: =M16 -> 1
B17: =DigDir!J17 -> 0 | C17: =DigDir!I17 -> 0 | L17: =DigDir!M17 -> -2.1804728 | M17: =DigDir!N17 -> 1.1 | O17: =ABS(L17-DigDir!$C$34) -> 2.5761473 | P17: =M17 -> 1.1
B18: =DigDir!J18 -> 0 | C18: =DigDir!I18 -> 0 | L18: =DigDir!M18 -> -2.1576611 | M18: =DigDir!N18 -> 1.2 | O18: =ABS(L18-DigDir!$C$34) -> 2.598959 | P18: =M18 -> 1.2
B19: =DigDir!J19 -> 0 | C19: =DigDir!I19 -> 0 | L19: =DigDir!M19 -> -2.140436 | M19: =DigDir!N19 -> 1.3 | O19: =ABS(L19-DigDir!$C$34) -> 2.6161841 | P19: =M19 -> 1.3
B20: =DigDir!J20 -> 0 | C20: =DigDir!I20 -> 0 | E20: Residual variance | G20: {=INDEX(B11:B22,MATCH(MIN(ABS(C11:C22-B8)),ABS(C11:C22-B8),0))} -> 0 | L20: =DigDir!M20 -> -2.140436 | M20: =DigDir!N20 -> 1.4 | O20: =ABS(L20-DigDir!$C$34) -> 2.6161841 | P20: =M20 -> 1.4
B21: =DigDir!J21 -> 0 | C21: =DigDir!I21 -> 0 | E21: Residual std. Error | G21: =SQRT(G20) -> 0 | L21: =DigDir!M21 -> -2.140436 | M21: =DigDir!N21 -> 1.5 | O21: =ABS(L21-DigDir!$C$34) -> 2.6161841 | P21: =M21 -> 1.5
B22: =DigDir!J22 -> 0 | C22: =DigDir!I22 -> 0 | L22: =DigDir!M22 -> -2.1246078 | M22: =DigDir!N22 -> 1.6 | O22: =ABS(L22-DigDir!$C$34) -> 2.6320123 | P22: =M22 -> 1.6
E23: Formula, see: | F23: https://www.excel-easy.com/examples/closest-match.html | L23: =DigDir!M23 -> -2.1017965 | M23: =DigDir!N23 -> 1.7 | O23: =ABS(L23-DigDir!$C$34) -> 2.6548236 | P23: =M23 -> 1.7
L24: =DigDir!M24 -> -2.082244 | M24: =DigDir!N24 -> 1.8 | O24: =ABS(L24-DigDir!$C$34) -> 2.6743761 | P24: =M24 -> 1.8
A25: Not assuming homoscedasticity, variance function | L25: =DigDir!M25 -> -2.082244 | M25: =DigDir!N25 -> 1.9 | O25: =ABS(L25-DigDir!$C$34) -> 2.6743761 | P25: =M25 -> 1.9
L26: =DigDir!M26 -> -2.082244 | M26: =DigDir!N26 -> 2 | O26: =ABS(L26-DigDir!$C$34) -> 2.6743761 | P26: =M26 -> 2
A27: =RAVLT_Learning!I26 | B27: =RAVLT_Learning!J26 -> Estimate | C27: X | D27: Beta x X | L27: =DigDir!M27 -> -2.0687435 | M27: =DigDir!N27 -> 2.1 | O27: =ABS(L27-DigDir!$C$34) -> 2.6878766 | P27: =M27 -> 2.1
A28: =DigDir!I27 -> 0 | B28: =DigDir!J27 -> 0 | C28: 1 | D28: =B28*C28 -> 0 | L28: =DigDir!M28 -> -2.0459322 | M28: =DigDir!N28 -> 2.2 | O28: =ABS(L28-DigDir!$C$34) -> 2.7106879 | P28: =M28 -> 2.2
A29: =DigDir!I28 -> 0 | B29: =DigDir!J28 -> 0 | C29: =B8 -> 5.9085465 | D29: =B29*C29 -> 0 | L29: =DigDir!M29 -> -2.024052 | M29: =DigDir!N29 -> 2.3 | O29: =ABS(L29-DigDir!$C$34) -> 2.7325681 | P29: =M29 -> 2.3
A30: =DigDir!I29 -> 0 | B30: =DigDir!J29 -> 0 | C30: =B8^2 -> 34.910922 | D30: =B30*C30 -> 0 | L30: =DigDir!M30 -> -2.024052 | M30: =DigDir!N30 -> 2.4 | O30: =ABS(L30-DigDir!$C$34) -> 2.7325681 | P30: =M30 -> 2.4
A31: =DigDir!I30 -> 0 | B31: =DigDir!J30 -> 0 | C31: =B8^3 -> 206.27281 | D31: =B31*C31 -> 0 | L31: =DigDir!M31 -> -2.024052 | M31: =DigDir!N31 -> 2.5 | O31: =ABS(L31-DigDir!$C$34) -> 2.7325681 | P31: =M31 -> 2.5
A32: =DigDir!I31 -> 0 | B32: =DigDir!J31 -> 0 | C32: =B8^4 -> 1218.7725 | D32: =B32*C32 -> 0 | L32: =DigDir!M32 -> -2.024052 | M32: =DigDir!N32 -> 2.6 | O32: =ABS(L32-DigDir!$C$34) -> 2.7325681 | P32: =M32 -> 2.6
A33: =DigDir!I32 -> 0 | B33: =DigDir!J32 -> 0 | C33: =B8^5 -> 7201.1739 | D33: =B33*C33 -> 0 | L33: =DigDir!M33 -> -2.024052 | M33: =DigDir!N33 -> 2.7 | O33: =ABS(L33-DigDir!$C$34) -> 2.7325681 | P33: =M33 -> 2.7
G34: =SQRT(D35) -> 0 | L34: =DigDir!M34 -> -2.024052 | M34: =DigDir!N34 -> 2.8 | O34: =ABS(L34-DigDir!$C$34) -> 2.7325681 | P34: =M34 -> 2.8
B35: Predicted VARIANCE | D35: =SUM(D28:D34) -> 0 | L35: =DigDir!M35 -> -2.002637 | M35: =DigDir!N35 -> 2.9 | O35: =ABS(L35-DigDir!$C$34) -> 2.7539831 | P35: =M35 -> 2.9
L36: =DigDir!M36 -> -1.9798253 | M36: =DigDir!N36 -> 3 | O36: =ABS(L36-DigDir!$C$34) -> 2.7767948 | P36: =M36 -> 3
A37: Checks | L37: =DigDir!M37 -> -1.9570138 | M37: =DigDir!N37 -> 3.1 | O37: =ABS(L37-DigDir!$C$34) -> 2.7996063 | P37: =M37 -> 3.1
A38: Overall resid std error entered | D38: =IF(G3>0, 1, 0) -> 1 | G38: Res. Std error | I38: =IF(D41=1, G3+G21+G34, ) -> 1.03194 | L38: =DigDir!M38 -> -1.9342026 | M38: =DigDir!N38 -> 3.2 | O38: =ABS(L38-DigDir!$C$34) -> 2.8224175 | P38: =M38 -> 3.2
A39: Resid std per group | D39: =IF(G21>0, 1, 0) -> 0 | I39: =IF(D41=1, " ", "ERROR!") | L39: =DigDir!M39 -> -1.9113913 | M39: =DigDir!N39 -> 3.3 | O39: =ABS(L39-DigDir!$C$34) -> 2.8452288 | P39: =M39 -> 3.3
A40: Variance function | D40: =IF(G34>0, 1, 0) -> 0 | L40: =DigDir!M40 -> -1.88858 | M40: =DigDir!N40 -> 3.4 | O40: =ABS(L40-DigDir!$C$34) -> 2.8680401 | P40: =M40 -> 3.4
C41: Som | D41: =SUM(D38:D40) -> 1 | E41: (check should be 1 to be OK) | L41: =DigDir!M41 -> -1.8657688 | M41: =DigDir!N41 -> 3.5 | O41: =ABS(L41-DigDir!$C$34) -> 2.8908513 | P41: =M41 -> 3.5
...

Sheet RAVLT_Rec
B1: ONLY MAKE CHANGES IN THE GREY HIGHLIGHTED CELLS | I1: =#REF! -> #REF!
A3: 1 | B3: COPY-PASTE FINAL STAGE 1 MEAN PREDICTION FUNCTION HERE: | H3: 2 | I3: COPY-PASTE FINAL STAGE 1 VARIANCE PREDICTION FUNCTION HERE: | L3: 3 | M3: COPY-PASTE PERCENTILE RANKS DELTA HERE:
C5: Estimate | H5: A | I5: Assuming homoscedasticity | M5: Delta | N5: Percentile rank
B6: (Intercept) | C6: 12.266165 | I6: Residual variance | M6: -3.376842 | N6: 0
B7: ageC | C7: -0.053962566 | M7: -3.1789388 | N7: 0.1
M8: -2.9810357 | N8: 0.2
H9: B | I9: Not assuming homoscedasticity, prediction-specific residual variances: | M9: -2.836123 | N9: 0.3
I10: Predicted test score | J10: Residual variance | M10: -2.836123 | N10: 0.4
M11: -2.836123 | N11: 0.5
M12: -2.831048 | N12: 0.6
M13: -2.8215711 | N13: 0.7
M14: -2.8120943 | N14: 0.8
M15: -2.8070289 | N15: 0.9
M16: -2.8030439 | N16: 1
M17: -2.7980566 | N17: 1.1
M18: -2.7799627 | N18: 1.2
M19: -2.7618688 | N19: 1.3
M20: -2.7280026 | N20: 1.4
M21: -2.6633553 | N21: 1.5
M22: -2.598708 | N22: 1.6
... M24: -2.4697221 | N24: 1.8
H25: C | I25: Not assuming homoscedasticity, continuous variance prediction function: | M25: -2.4052669 | N25: 1.9
J26: Estimate | M26: -2.3969426 | N26: 2
A27: 4 | B27: Predicted test score: | C27: =C6+(C7*('Normative data'!C6-71.20708447)) -> 12.870928 | I27: (Intercept) | J27: 12426.33 | M27: -2.3966872 | N27: 2.1
B28: [SPECIFY THE APPROPRIATE FORMULA IN CELL B27 TO COMPUTE | I28: Pred.Y | J28: -3071.3827 | M28: -2.396022 | N28: 2.2
B29: THE PREDICTED TEST SCORE BASED ON THE INPUT PROVIDED | I29: Pred.Y.2 | J29: 252.93887 | M29: -2.3928832 | N29: 2.3
B30: IN SHEET 1 (E.G. SPECIFIED GENDER) + COPY-PASTED STAGE 1 MODEL] | I30: Pred.Y.3 | J30: -6.9378657 | M30: -2.3897444 | N30: 2.4
M31: -2.3856358 | N31: 2.5
M32: -2.3801308 | N32: 2.6
B33: Computed residual: | C33: ='Normative data'!#REF!-RAVLT_Rec!C27 -> #REF! | M33: -2.3746258 | N33: 2.7
B34: Std. Residual: | C34: =C33/SD_PERC_RAVLTR!I38 -> #REF! | I34: Residual Std.Error to be used: | J34: =SD_PERC_RAVLTR!I38 -> 15.353758 | M34: -2.3710106 | N34: 2.8
M35: -2.3682945 | N35: 2.9
M36: -2.3655784 | N36: 3
M37: -2.3411789 | N37: 3.1
M38: -2.3155259 | N38: 3.2
M39: -2.2820021 | N39: 3.3
M40: -2.2194164 | N40: 3.4
M41: -2.1568308 | N41: 3.5
M42: -2.095222 | N42: 3.6
M43: -2.0346676 | N43: 3.7
...

Sheet SD_PERC_RAVLTL
