Workbook

Sheet Normative data
B2: Regression Based Normative Data
B4: Please fill in the relevant independent variables:
B6: Age | D6: Years
B7: Sex | D7: Male = 1; Female = 0
B8: Years of Education | D8: Years
B11: Please fill in the raw test score: | D11: Predicted Test score | E11: Residual | F11: Residual Standard Error | G11: Standardarized Residual (z-score)
B12: RAVLT Learning | D12: =RAVLT_Learning!C27 -> 65.717594 | E12: =RAVLT_Learning!C33 -> -65.717594 | F12: =RAVLT_Learning!J34 -> 7.79268 | G12: =RAVLT_Learning!C34 -> -8.4332468
B13: RAVLT Delayed | D13: =RAVLT_Delayed!C27 -> 15.500337 | E13: =RAVLT_Delayed!C33 -> -15.500337 | F13: =RAVLT_Delayed!J34 -> 10.143881 | G13: =RAVLT_Delayed!C34 -> -1.528048
B14: Digit Span Forward | D14: =DigDir!C27 -> 5.2287602 | E14: =DigDir!C33 -> -5.2287602 | F14: =DigDir!J34 -> 1.040915 | G14: =(C14-6.103542234)/1.019033876 -> -5.9895381
B15: Digit Span Backward | D15: =DigInv!C27 -> 4.7129471 | E15: =DigInv!C33 -> -4.7129471 | F15: =DigInv!J34 -> 1.0698893 | G15: =DigInv!C34 -> -4.405079
B16: Trail Making Test A | D16: =TMTA!C27 -> -11.618446 | E16: =TMTA!C33 -> 11.618446 | F16: =TMTA!J34 -> 13.675132 | G16: =TMTA!C34 -> -0.84960395
B17: Trail Making Test B | D17: =TMTB!C27 -> -16.515674 | E17: =TMTB!C33 -> 16.515674 | F17: =TMTB!J34 -> 147.40576 | G17: =TMTB!C34 -> -0.11204225
B18: Semantic Fluency | D18: =SEM!C27 -> 32.679672 | E18: =SEM!C33 -> -32.679672 | F18: =SEM!J34 -> 4.212312 | G18: =SEM!C34 -> -7.7581319
B19: Phonological Fluency | D19: =FONO!C27 -> 19.496085 | E19: =FONO!C33 -> -19.496085 | F19: =FONO!J34 -> 4.32359 | G19: =FONO!C34 -> -4.5092354

Sheet SEM
B1: ONLY MAKE CHANGES IN THE GREY HIGHLIGHTED CELLS | I1: =SD_PERC_SEM!A42
A3: 1 | B3: COPY-PASTE FINAL STAGE 1 MEAN PREDICTION FUNCTION HERE: | H3: 2 | I3: COPY-PASTE FINAL STAGE 1 VARIANCE PREDICTION FUNCTION HERE: | L3: 3 | M3: COPY-PASTE PERCENTILE RANKS DELTA HERE:
C5: Estimate | H5: A | I5: Assuming homoscedasticity | M5: Delta | N5: Percentile rank
B6: (Intercept) | C6: 18.092832 | I6: Residual variance | J6: 17.743572 | M6: -2.377832 | N6: 0
B7: ageC | C7: -0.20464142 | M7: -2.3707492 | N7: 0.1
B8: years_education | C8: 0.17360781 | M8: -2.3636663 | N8: 0.2
H9: B | I9: Not assuming homoscedasticity, prediction-specific residual variances: | M9: -2.3527919 | N9: 0.3
I10: Predicted test score | J10: Residual variance | M10: -2.3205985 | N10: 0.4
M11: -2.2884052 | N11: 0.5
M12: -2.2525676 | N12: 0.6
M13: -2.2083072 | N13: 0.7
M14: -2.1640468 | N14: 0.8
M15: -2.1383589 | N15: 0.9
M16: -2.1350981 | N16: 1
M17: -2.1318373 | N17: 1.1
M18: -2.1211748 | N18: 1.2
M19: -2.1056591 | N19: 1.3
M20: -2.0901435 | N20: 1.4
M21: -2.0392422 | N21: 1.5
M22: -1.9768572 | N22: 1.6
... M24: -1.879461 | N24: 1.8
H25: C | I25: Not assuming homoscedasticity, continuous variance prediction function: | M25: -1.8472905 | N25: 1.9
J26: Estimate | M26: -1.8162017 | N26: 2
A27: 4 | B27: Predicted test score: | C27: =C6+(C7*('Normative data'!C6-71.28))+(SEM!C8*'Normative data'!C8) -> 32.679672 | M27: -1.8030171 | N27: 2.1
B28: [SPECIFY THE APPROPRIATE FORMULA IN CELL B27 TO COMPUTE | M28: -1.7898325 | N28: 2.2
B29: THE PREDICTED TEST SCORE BASED ON THE INPUT PROVIDED | M29: -1.7759792 | N29: 2.3
B30: IN SHEET 1 (E.G. SPECIFIED GENDER) + COPY-PASTED STAGE 1 MODEL] | M30: -1.7595794 | N30: 2.4
M31: -1.7431797 | N31: 2.5
M32: -1.7317468 | N32: 2.6
B33: Computed residual: | C33: ='Normative data'!C18-SEM!C27 -> -32.679672 | M33: -1.7291835 | N33: 2.7
B34: Std. Residual: | C34: =(C33/SD_PERC_SEM!I38) -> -7.7581319 | I34: Residual Std.Error to be used: | J34: =SD_PERC_SEM!I38 -> 4.212312 | M34: -1.7266201 | N34: 2.8
M35: -1.7176541 | N35: 2.9
M36: -1.7025358 | N36: 3
M37: -1.6874176 | N37: 3.1
M38: -1.672715 | N38: 3.2
M39: -1.6582258 | N39: 3.3
M40: -1.6437365 | N40: 3.4
M41: -1.6342019 | N41: 3.5
M42: -1.6258148 | N42: 3.6
M43: -1.6174276 | N43: 3.7
...

Sheet SD_PERC_SEM
A1: Determine SD(residual) to use; DO NOT MAKE CHANGES HERE | L1: Determine percentile
A3: Assuming homoscedasticity | G3: =SQRT(SEM!J6) -> 4.212312
L4: =RAVLT_Learning!M5 -> Delta | M4: =RAVLT_Learning!N5 -> Percentile rank | O4: Abs diff delta | P4: Percentile
L5: =SEM!M6 -> -2.377832 | M5: =SEM!N6 -> 0 | O5: =ABS(L5-SEM!$C$34) -> 5.3802999 | P5: =M5 -> 0
A6: Not assuming homoscedasticity, residual std.error per group: | L6: =SEM!M7 -> -2.3707492 | M6: =SEM!N7 -> 0.1 | O6: =ABS(L6-SEM!$C$34) -> 5.3873827 | P6: =M6 -> 0.1
L7: =SEM!M8 -> -2.3636663 | M7: =SEM!N8 -> 0.2 | O7: =ABS(L7-SEM!$C$34) -> 5.3944655 | P7: =M7 -> 0.2
A8: Predicted score: | B8: =SEM!C27 -> 32.679672
L9: =SEM!M9 -> -2.3527919 | M9: =SEM!N9 -> 0.3 | O9: =ABS(L9-SEM!$C$34) -> 5.40534 | P9: =M9 -> 0.3
B10: =RAVLT_Learning!J10 -> Residual variance | C10: =RAVLT_Learning!I10 -> Predicted test score | L10: =SEM!M10 -> -2.3205985 | M10: =SEM!N10 -> 0.4 | O10: =ABS(L10-SEM!$C$34) -> 5.4375333 | P10: =M10 -> 0.4
B11: =SEM!J11 -> 0 | C11: =SEM!I11 -> 0 | L11: =SEM!M11 -> -2.2884052 | M11: =SEM!N11 -> 0.5 | O11: =ABS(L11-SEM!$C$34) -> 5.4697267 | P11: =M11 -> 0.5
B12: =SEM!J12 -> 0 | C12: =SEM!I12 -> 0 | L12: =SEM!M12 -> -2.2525676 | M12: =SEM!N12 -> 0.6 | O12: =ABS(L12-SEM!$C$34) -> 5.5055642 | P12: =M12 -> 0.6
B13: =SEM!J13 -> 0 | C13: =SEM!I13 -> 0 | L13: =SEM!M13 -> -2.2083072 | M13: =SEM!N13 -> 0.7 | O13: =ABS(L13-SEM!$C$34) -> 5.5498246 | P13: =M13 -> 0.7
B14: =SEM!J14 -> 0 | C14: =SEM!I14 -> 0 | L14: =SEM!M14 -> -2.1640468 | M14: =SEM!N14 -> 0.8 | O14: =ABS(L14-SEM!$C$34) -> 5.594085 | P14: =M14 -> 0.8
B15: =SEM!J15 -> 0 | C15: =SEM!I15 -> 0 | L15: =SEM!M15 -> -2.1383589 | M15: =SEM!N15 -> 0.9 | O15: =ABS(L15-SEM!$C$34) -> 5.619773 | P15: =M15 -> 0.9
B16: =SEM!J16 -> 0 | C16: =SEM!I16 -> 0 | L16: =SEM!M16 -> -2.1350981 | M16: =SEM!N16 -> 1 | O16: =ABS(L16-SEM!$C$34) -> 5.6230338 | P16: =M16 -> 1
B17: =SEM!J17 -> 0 | C17: =SEM!I17 -> 0 | L17: =SEM!M17 -> -2.1318373 | M17: =SEM!N17 -> 1.1 | O17: =ABS(L17-SEM!$C$34) -> 5.6262945 | P17: =M17 -> 1.1
B18: =SEM!J18 -> 0 | C18: =SEM!I18 -> 0 | L18: =SEM!M18 -> -2.1211748 | M18: =SEM!N18 -> 1.2 | O18: =ABS(L18-SEM!$C$34) -> 5.6369571 | P18: =M18 -> 1.2
B19: =SEM!J19 -> 0 | C19: =SEM!I19 -> 0 | L19: =SEM!M19 -> -2.1056591 | M19: =SEM!N19 -> 1.3 | O19: =ABS(L19-SEM!$C$34) -> 5.6524727 | P19: =M19 -> 1.3
B20: =SEM!J20 -> 0 | C20: =SEM!I20 -> 0 | E20: Residual variance | G20: {=INDEX(B11:B22,MATCH(MIN(ABS(C11:C22-B8)),ABS(C11:C22-B8),0))} -> 0 | L20: =SEM!M20 -> -2.0901435 | M20: =SEM!N20 -> 1.4 | O20: =ABS(L20-SEM!$C$34) -> 5.6679883 | P20: =M20 -> 1.4
B21: =SEM!J21 -> 0 | C21: =SEM!I21 -> 0 | E21: Residual std. Error | G21: =SQRT(G20) -> 0 | L21: =SEM!M21 -> -2.0392422 | M21: =SEM!N21 -> 1.5 | O21: =ABS(L21-SEM!$C$34) -> 5.7188896 | P21: =M21 -> 1.5
B22: =SEM!J22 -> 0 | C22: =SEM!I22 -> 0 | L22: =SEM!M22 -> -1.9768572 | M22: =SEM!N22 -> 1.6 | O22: =ABS(L22-SEM!$C$34) -> 5.7812746 | P22: =M22 -> 1.6
E23: Formula, see: | F23: https://www.excel-easy.com/examples/closest-match.html | L23: =SEM!M23 -> -1.9144723 | M23: =SEM!N23 -> 1.7 | O23: =ABS(L23-SEM!$C$34) -> 5.8436596 | P23: =M23 -> 1.7
L24: =SEM!M24 -> -1.879461 | M24: =SEM!N24 -> 1.8 | O24: =ABS(L24-SEM!$C$34) -> 5.8786708 | P24: =M24 -> 1.8
A25: Not assuming homoscedasticity, variance function | L25: =SEM!M25 -> -1.8472905 | M25: =SEM!N25 -> 1.9 | O25: =ABS(L25-SEM!$C$34) -> 5.9108414 | P25: =M25 -> 1.9
L26: =SEM!M26 -> -1.8162017 | M26: =SEM!N26 -> 2 | O26: =ABS(L26-SEM!$C$34) -> 5.9419301 | P26: =M26 -> 2
A27: =RAVLT_Learning!I26 | B27: =RAVLT_Learning!J26 -> Estimate | C27: X | D27: Beta x X | L27: =SEM!M27 -> -1.8030171 | M27: =SEM!N27 -> 2.1 | O27: =ABS(L27-SEM!$C$34) -> 5.9551147 | P27: =M27 -> 2.1
A28: =SEM!I27 -> 0 | B28: =SEM!J27 -> 0 | C28: 1 | D28: =B28*C28 -> 0 | L28: =SEM!M28 -> -1.7898325 | M28: =SEM!N28 -> 2.2 | O28: =ABS(L28-SEM!$C$34) -> 5.9682993 | P28: =M28 -> 2.2
A29: =SEM!I28 -> 0 | B29: =SEM!J28 -> 0 | C29: =B8 -> 32.679672 | D29: =B29*C29 -> 0 | L29: =SEM!M29 -> -1.7759792 | M29: =SEM!N29 -> 2.3 | O29: =ABS(L29-SEM!$C$34) -> 5.9821526 | P29: =M29 -> 2.3
A30: =SEM!I29 -> 0 | B30: =SEM!J29 -> 0 | C30: =B8^2 -> 1067.961 | D30: =B30*C30 -> 0 | L30: =SEM!M30 -> -1.7595794 | M30: =SEM!N30 -> 2.4 | O30: =ABS(L30-SEM!$C$34) -> 5.9985524 | P30: =M30 -> 2.4
A31: =SEM!I30 -> 0 | B31: =SEM!J30 -> 0 | C31: =B8^3 -> 34900.614 | D31: =B31*C31 -> 0 | L31: =SEM!M31 -> -1.7431797 | M31: =SEM!N31 -> 2.5 | O31: =ABS(L31-SEM!$C$34) -> 6.0149522 | P31: =M31 -> 2.5
A32: =SEM!I31 -> 0 | B32: =SEM!J31 -> 0 | C32: =B8^4 -> 1140540.6 | D32: =B32*C32 -> 0 | L32: =SEM!M32 -> -1.7317468 | M32: =SEM!N32 -> 2.6 | O32: =ABS(L32-SEM!$C$34) -> 6.026385 | P32: =M32 -> 2.6
A33: =SEM!I32 -> 0 | B33: =SEM!J32 -> 0 | C33: =B8^5 -> 37272493 | D33: =B33*C33 -> 0 | L33: =SEM!M33 -> -1.7291835 | M33: =SEM!N33 -> 2.7 | O33: =ABS(L33-SEM!$C$34) -> 6.0289484 | P33: =M33 -> 2.7
G34: =SQRT(D35) -> 0 | L34: =SEM!M34 -> -1.7266201 | M34: =SEM!N34 -> 2.8 | O34: =ABS(L34-SEM!$C$34) -> 6.0315117 | P34: =M34 -> 2.8
B35: Predicted VARIANCE | D35: =SUM(D28:D34) -> 0 | L35: =SEM!M35 -> -1.7176541 | M35: =SEM!N35 -> 2.9 | O35: =ABS(L35-SEM!$C$34) -> 6.0404777 | P35: =M35 -> 2.9
L36: =SEM!M36 -> -1.7025358 | M36: =SEM!N36 -> 3 | O36: =ABS(L36-SEM!$C$34) -> 6.055596 | P36: =M36 -> 3
A37: Checks | L37: =SEM!M37 -> -1.6874176 | M37: =SEM!N37 -> 3.1 | O37: =ABS(L37-SEM!$C$34) -> 6.0707143 | P37: =M37 -> 3.1
A38: Overall resid std error entered | D38: =IF(G3>0, 1, 0) -> 1 | G38: Res. Std error | I38: =IF(D41=1, G3+G21+G34, ) -> 4.212312 | L38: =SEM!M38 -> -1.672715 | M38: =SEM!N38 -> 3.2 | O38: =ABS(L38-SEM!$C$34) -> 6.0854168 | P38: =M38 -> 3.2
A39: Resid std per group | D39: =IF(G21>0, 1, 0) -> 0 | I39: =IF(D41=1, " ", "ERROR!") | L39: =SEM!M39 -> -1.6582258 | M39: =SEM!N39 -> 3.3 | O39: =ABS(L39-SEM!$C$34) -> 6.0999061 | P39: =M39 -> 3.3
A40: Variance function | D40: =IF(G34>0, 1, 0) -> 0 | L40: =SEM!M40 -> -1.6437365 | M40: =SEM!N40 -> 3.4 | O40: =ABS(L40-SEM!$C$34) -> 6.1143954 | P40: =M40 -> 3.4
C41: Som | D41: =SUM(D38:D40) -> 1 | E41: (check should be 1 to be OK) | L41: =SEM!M41 -> -1.6342019 | M41: =SEM!N41 -> 3.5 | O41: =ABS(L41-SEM!$C$34) -> 6.1239299 | P41: =M41 -> 3.5
...

Sheet FONO
B1: ONLY MAKE CHANGES IN THE GREY HIGHLIGHTED CELLS | I1: =SD_PERC_FONO!A42
A3: 1 | B3: COPY-PASTE FINAL STAGE 1 MEAN PREDICTION FUNCTION HERE: | H3: 2 | I3: COPY-PASTE FINAL STAGE 1 VARIANCE PREDICTION FUNCTION HERE: | L3: 3 | M3: COPY-PASTE PERCENTILE RANKS DELTA HERE:
C5: Estimate | H5: A | I5: Assuming homoscedasticity | M5: Delta | N5: Percentile rank
B6: (Intercept) | C6: 13.601097 | I6: Residual variance | J6: 18.69343 | M6: -2.880255 | N6: 0
B7: ageC | C7: -0.08270185 | M7: -2.8291964 | N7: 0.1
B8: years_education | C8: 0.26553706 | M8: -2.7781379 | N8: 0.2
B9: sex1 | C9: -2.0994006 | H9: B | I9: Not assuming homoscedasticity, prediction-specific residual variances: | M9: -2.7134066 | N9: 0.3
I10: Predicted test score | J10: Residual variance | M10: -2.5717988 | N10: 0.4
M11: -2.430191 | N11: 0.5
M12: -2.3239246 | N12: 0.6
M13: -2.2993434 | N13: 0.7
M14: -2.2747621 | N14: 0.8
M15: -2.236985 | N15: 0.9
M16: -2.1832733 | N16: 1
M17: -2.1295615 | N17: 1.1
M18: -2.0950524 | N18: 1.2
M19: -2.0731339 | N19: 1.3
M20: -2.0512154 | N20: 1.4
M21: -2.0145912 | N21: 1.5
M22: -1.9731946 | N22: 1.6
... M24: -1.896148 | N24: 1.8
H25: C | I25: Not assuming homoscedasticity, continuous variance prediction function: | M25: -1.8610943 | N25: 1.9
J26: Estimate | M26: -1.8243915 | N26: 2
A27: 4 | B27: Predicted test score: | C27: =C6+(C7*('Normative data'!C6-71.28))+(FONO!C8*'Normative data'!C8)+(C9*'Normative data'!C7) -> 19.496085 | M27: -1.7603954 | N27: 2.1
B28: [SPECIFY THE APPROPRIATE FORMULA IN CELL B27 TO COMPUTE | M28: -1.6963994 | N28: 2.2
B29: THE PREDICTED TEST SCORE BASED ON THE INPUT PROVIDED | M29: -1.639758 | N29: 2.3
B30: IN SHEET 1 (E.G. SPECIFIED GENDER) + COPY-PASTED STAGE 1 MODEL] | M30: -1.6111252 | N30: 2.4
M31: -1.5824924 | N31: 2.5
M32: -1.5626315 | N32: 2.6
B33: Computed residual: | C33: ='Normative data'!C19-FONO!C27 -> -19.496085 | M33: -1.558435 | N33: 2.7
B34: Std. Residual: | C34: =(C33/SD_PERC_FONO!I38) -> -4.5092354 | I34: Residual Std.Error to be used: | J34: =SD_PERC_FONO!I38 -> 4.32359 | M34: -1.5542384 | N34: 2.8
M35: -1.5480668 | N35: 2.9
M36: -1.5399973 | N36: 3
M37: -1.5319278 | N37: 3.1
M38: -1.5267924 | N38: 3.2
M39: -1.523162 | N39: 3.3
M40: -1.5195316 | N40: 3.4
M41: -1.5162968 | N41: 3.5
M42: -1.5131536 | N42: 3.6
M43: -1.5100104 | N43: 3.7
...

Sheet SD_PERC_FONO
A1: Determine SD(residual) to use; DO NOT MAKE CHANGES HERE | L1: Determine percentile
A3: Assuming homoscedasticity | G3: =SQRT(FONO!J6) -> 4.32359
L4: =RAVLT_Learning!M5 -> Delta | M4: =RAVLT_Learning!N5 -> Percentile rank | O4: Abs diff delta | P4: Percentile
L5: =FONO!M6 -> -2.880255 | M5: =FONO!N6 -> 0 | O5: =ABS(L5-FONO!$C$34) -> 1.6289804 | P5: =M5 -> 0
A6: Not assuming homoscedasticity, residual std.error per group: | L6: =FONO!M7 -> -2.8291964 | M6: =FONO!N7 -> 0.1 | O6: =ABS(L6-FONO!$C$34) -> 1.680039 | P6: =M6 -> 0.1
L7: =FONO!M8 -> -2.7781379 | M7: =FONO!N8 -> 0.2 | O7: =ABS(L7-FONO!$C$34) -> 1.7310975 | P7: =M7 -> 0.2
A8: Predicted score: | B8: =FONO!C27 -> 19.496085
L9: =FONO!M9 -> -2.7134066 | M9: =FONO!N9 -> 0.3 | O9: =ABS(L9-FONO!$C$34) -> 1.7958288 | P9: =M9 -> 0.3
B10: =RAVLT_Learning!J10 -> Residual variance | C10: =RAVLT_Learning!I10 -> Predicted test score | L10: =FONO!M10 -> -2.5717988 | M10: =FONO!N10 -> 0.4 | O10: =ABS(L10-FONO!$C$34) -> 1.9374366 | P10: =M10 -> 0.4
B11: =FONO!J11 -> 0 | C11: =FONO!I11 -> 0 | L11: =FONO!M11 -> -2.430191 | M11: =FONO!N11 -> 0.5 | O11: =ABS(L11-FONO!$C$34) -> 2.0790443 | P11: =M11 -> 0.5
B12: =FONO!J12 -> 0 | C12: =FONO!I12 -> 0 | L12: =FONO!M12 -> -2.3239246 | M12: =FONO!N12 -> 0.6 | O12: =ABS(L12-FONO!$C$34) -> 2.1853108 | P12: =M12 -> 0.6
B13: =FONO!J13 -> 0 | C13: =FONO!I13 -> 0 | L13: =FONO!M13 -> -2.2993434 | M13: =FONO!N13 -> 0.7 | O13: =ABS(L13-FONO!$C$34) -> 2.209892 | P13: =M13 -> 0.7
B14: =FONO!J14 -> 0 | C14: =FONO!I14 -> 0 | L14: =FONO!M14 -> -2.2747621 | M14: =FONO!N14 -> 0.8 | O14: =ABS(L14-FONO!$C$34) -> 2.2344732 | P14: =M14 -> 0.8
B15: =FONO!J15 -> 0 | C15: =FONO!I15 -> 0 | L15: =FONO!M15 -> -2.236985 | M15: =FONO!N15 -> 0.9 | O15: =ABS(L15-FONO!$C$34) -> 2.2722504 | P15: =M15 -> 0.9
B16: =FONO!J16 -> 0 | C16: =FONO!I16 -> 0 | L16: =FONO!M16 -> -2.1832733 | M16: =FONO!N16 -> 1 | O16: =ABS(L16-FONO!$C$34) -> 2.3259621 | P16: =M16 -> 1
B17: =FONO!J17 -> 0 | C17: =FONO!I17 -> 0 | L17: =FONO!M17 -> -2.1295615 | M17: =FONO!N17 -> 1.1 | O17: =ABS(L17-FONO!$C$34) -> 2.3796739 | P17: =M17 -> 1.1
B18: =FONO!J18 -> 0 | C18: =FONO!I18 -> 0 | L18: =FONO!M18 -> -2.0950524 | M18: =FONO!N18 -> 1.2 | O18: =ABS(L18-FONO!$C$34) -> 2.4141829 | P18: =M18 -> 1.2
B19: =FONO!J19 -> 0 | C19: =FONO!I19 -> 0 | L19: =FONO!M19 -> -2.0731339 | M19: =FONO!N19 -> 1.3 | O19: =ABS(L19-FONO!$C$34) -> 2.4361015 | P19: =M19 -> 1.3
B20: =FONO!J20 -> 0 | C20: =FONO!I20 -> 0 | E20: Residual variance | G20: {=INDEX(B11:B22,MATCH(MIN(ABS(C11:C22-B8)),ABS(C11:C22-B8),0))} -> 0 | L20: =FONO!M20 -> -2.0512154 | M20: =FONO!N20 -> 1.4 | O20: =ABS(L20-FONO!$C$34) -> 2.45802 | P20: =M20 -> 1.4
B21: =FONO!J21 -> 0 | C21: =FONO!I21 -> 0 | E21: Residual std. Error | G21: =SQRT(G20) -> 0 | L21: =FONO!M21 -> -2.0145912 | M21: =FONO!N21 -> 1.5 | O21: =ABS(L21-FONO!$C$34) -> 2.4946442 | P21: =M21 -> 1.5
B22: =FONO!J22 -> 0 | C22: =FONO!I22 -> 0 | L22: =FONO!M22 -> -1.9731946 | M22: =FONO!N22 -> 1.6 | O22: =ABS(L22-FONO!$C$34) -> 2.5360408 | P22: =M22 -> 1.6
E23: Formula, see: | F23: https://www.excel-easy.com/examples/closest-match.html | L23: =FONO!M23 -> -1.931798 | M23: =FONO!N23 -> 1.7 | O23: =ABS(L23-FONO!$C$34) -> 2.5774374 | P23: =M23 -> 1.7
L24: =FONO!M24 -> -1.896148 | M24: =FONO!N24 -> 1.8 | O24: =ABS(L24-FONO!$C$34) -> 2.6130874 | P24: =M24 -> 1.8
A25: Not assuming homoscedasticity, variance function | L25: =FONO!M25 -> -1.8610943 | M25: =FONO!N25 -> 1.9 | O25: =ABS(L25-FONO!$C$34) -> 2.6481411 | P25: =M25 -> 1.9
L26: =FONO!M26 -> -1.8243915 | M26: =FONO!N26 -> 2 | O26: =ABS(L26-FONO!$C$34) -> 2.6848439 | P26: =M26 -> 2
A27: =RAVLT_Learning!I26 | B27: =RAVLT_Learning!J26 -> Estimate | C27: X | D27: Beta x X | L27: =FONO!M27 -> -1.7603954 | M27: =FONO!N27 -> 2.1 | O27: =ABS(L27-FONO!$C$34) -> 2.74884 | P27: =M27 -> 2.1
A28: =FONO!I27 -> 0 | B28: =FONO!J27 -> 0 | C28: 1 | D28: =B28*C28 -> 0 | L28: =FONO!M28 -> -1.6963994 | M28: =FONO!N28 -> 2.2 | O28: =ABS(L28-FONO!$C$34) -> 2.812836 | P28: =M28 -> 2.2
A29: =FONO!I28 -> 0 | B29: =FONO!J28 -> 0 | C29: =B8 -> 19.496085 | D29: =B29*C29 -> 0 | L29: =FONO!M29 -> -1.639758 | M29: =FONO!N29 -> 2.3 | O29: =ABS(L29-FONO!$C$34) -> 2.8694774 | P29: =M29 -> 2.3
A30: =FONO!I29 -> 0 | B30: =FONO!J29 -> 0 | C30: =B8^2 -> 380.09733 | D30: =B30*C30 -> 0 | L30: =FONO!M30 -> -1.6111252 | M30: =FONO!N30 -> 2.4 | O30: =ABS(L30-FONO!$C$34) -> 2.8981102 | P30: =M30 -> 2.4
A31: =FONO!I30 -> 0 | B31: =FONO!J30 -> 0 | C31: =B8^3 -> 7410.4099 | D31: =B31*C31 -> 0 | L31: =FONO!M31 -> -1.5824924 | M31: =FONO!N31 -> 2.5 | O31: =ABS(L31-FONO!$C$34) -> 2.926743 | P31: =M31 -> 2.5
A32: =FONO!I31 -> 0 | B32: =FONO!J31 -> 0 | C32: =B8^4 -> 144473.98 | D32: =B32*C32 -> 0 | L32: =FONO!M32 -> -1.5626315 | M32: =FONO!N32 -> 2.6 | O32: =ABS(L32-FONO!$C$34) -> 2.9466038 | P32: =M32 -> 2.6
A33: =FONO!I32 -> 0 | B33: =FONO!J32 -> 0 | C33: =B8^5 -> 2816677 | D33: =B33*C33 -> 0 | L33: =FONO!M33 -> -1.558435 | M33: =FONO!N33 -> 2.7 | O33: =ABS(L33-FONO!$C$34) -> 2.9508004 | P33: =M33 -> 2.7
G34: =SQRT(D35) -> 0 | L34: =FONO!M34 -> -1.5542384 | M34: =FONO!N34 -> 2.8 | O34: =ABS(L34-FONO!$C$34) -> 2.954997 | P34: =M34 -> 2.8
B35: Predicted VARIANCE | D35: =SUM(D28:D34) -> 0 | L35: =FONO!M35 -> -1.5480668 | M35: =FONO!N35 -> 2.9 | O35: =ABS(L35-FONO!$C$34) -> 2.9611686 | P35: =M35 -> 2.9
L36: =FONO!M36 -> -1.5399973 | M36: =FONO!N36 -> 3 | O36: =ABS(L36-FONO!$C$34) -> 2.9692381 | P36: =M36 -> 3
A37: Checks | L37: =FONO!M37 -> -1.5319278 | M37: =FONO!N37 -> 3.1 | O37: =ABS(L37-FONO!$C$34) -> 2.9773076 | P37: =M37 -> 3.1
A38: Overall resid std error entered | D38: =IF(G3>0, 1, 0) -> 1 | G38: Res. Std error | I38: =IF(D41=1, G3+G21+G34, ) -> 4.32359 | L38: =FONO!M38 -> -1.5267924 | M38: =FONO!N38 -> 3.2 | O38: =ABS(L38-FONO!$C$34) -> 2.982443 | P38: =M38 -> 3.2
A39: Resid std per group | D39: =IF(G21>0, 1, 0) -> 0 | I39: =IF(D41=1, " ", "ERROR!") | L39: =FONO!M39 -> -1.523162 | M39: =FONO!N39 -> 3.3 | O39: =ABS(L39-FONO!$C$34) -> 2.9860734 | P39: =M39 -> 3.3
A40: Variance function | D40: =IF(G34>0, 1, 0) -> 0 | L40: =FONO!M40 -> -1.5195316 | M40: =FONO!N40 -> 3.4 | O40: =ABS(L40-FONO!$C$34) -> 2.9897038 | P40: =M40 -> 3.4
C41: Som | D41: =SUM(D38:D40) -> 1 | E41: (check should be 1 to be OK) | L41: =FONO!M41 -> -1.5162968 | M41: =FONO!N41 -> 3.5 | O41: =ABS(L41-FONO!$C$34) -> 2.9929386 | P41: =M41 -> 3.5
...

Sheet TMTB
B1: ONLY MAKE CHANGES IN THE GREY HIGHLIGHTED CELLS | I1: =SD_PERC_TMTB!A42
A3: 1 | B3: COPY-PASTE FINAL STAGE 1 MEAN PREDICTION FUNCTION HERE: | H3: 2 | I3: COPY-PASTE FINAL STAGE 1 VARIANCE PREDICTION FUNCTION HERE: | L3: 3 | M3: COPY-PASTE PERCENTILE RANKS DELTA HERE:
C5: Estimate | H5: A | I5: Assuming homoscedasticity | M5: Delta | N5: Percentile rank
B6: (Intercept) | C6: 137.25124 | I6: Residual variance | M6: -1.632027 | N6: 0
B7: ageC | C7: 2.1572238 | M7: -1.5705501 | N7: 0.1
B8: years_education | C8: -2.9532056 | M8: -1.5090731 | N8: 0.2
H9: B | I9: Not assuming homoscedasticity, prediction-specific residual variances: | M9: -1.4546968 | N9: 0.3
I10: Predicted test score | J10: Residual variance | M10: -1.4402447 | N10: 0.4
M11: -1.4257926 | N11: 0.5
M12: -1.410221 | N12: 0.6
M13: -1.3920616 | N13: 0.7
M14: -1.3739023 | N14: 0.8
M15: -1.3637863 | N15: 0.9
M16: -1.363383 | N16: 1
M17: -1.3629797 | N17: 1.1
M18: -1.3554729 | N18: 1.2
M19: -1.3433087 | N19: 1.3
M20: -1.3311444 | N20: 1.4
M21: -1.3274228 | N21: 1.5
M22: -1.326441 | N22: 1.6
... M24: -1.3047685 | N24: 1.8
H25: C | I25: Not assuming homoscedasticity, continuous variance prediction function: | M25: -1.2820325 | N25: 1.9
J26: Estimate | M26: -1.2604238 | N26: 2
A27: 4 | B27: Predicted test score: | C27: =C6+(C7*('Normative data'!C6-71.28))+(TMTB!C8*'Normative data'!C8) -> -16.515674 | I27: (Intercept) | J27: 13730.003 | M27: -1.2574719 | N27: 2.1
B28: [SPECIFY THE APPROPRIATE FORMULA IN CELL B27 TO COMPUTE | I28: Pred.Y | J28: -413.0929 | M28: -1.25452 | N28: 2.2
B29: THE PREDICTED TEST SCORE BASED ON THE INPUT PROVIDED | I29: Pred.Y.2 | J29: 4.1126815 | M29: -1.2508314 | N29: 2.3
B30: IN SHEET 1 (E.G. SPECIFIED GENDER) + COPY-PASTED STAGE 1 MODEL] | I30: Pred.Y.3 | J30: -0.012018306 | M30: -1.2443372 | N30: 2.4
M31: -1.237843 | N31: 2.5
M32: -1.2320095 | N32: 2.6
B33: Computed residual: | C33: ='Normative data'!C17-TMTB!C27 -> 16.515674 | M33: -1.2273559 | N33: 2.7
B34: Std. Residual: | C34: =-(C33/SD_PERC_TMTB!I38) -> -0.11204225 | I34: Residual Std.Error to be used: | J34: =SD_PERC_TMTB!I38 -> 147.40576 | M34: -1.2227024 | N34: 2.8
M35: -1.2201875 | N35: 2.9
M36: -1.2197277 | N36: 3
M37: -1.2192679 | N37: 3.1
M38: -1.212497 | N38: 3.2
M39: -1.2024889 | N39: 3.3
M40: -1.1924809 | N40: 3.4
M41: -1.1766859 | N41: 3.5
M42: -1.1595508 | N42: 3.6
M43: -1.1424156 | N43: 3.7
...

Sheet SD_PERC_TMTB
A1: Determine SD(residual) to use; DO NOT MAKE CHANGES HERE | L1: Determine percentile
A3: Assuming homoscedasticity | G3: =SQRT(TMTB!J6) -> 0
L4: =RAVLT_Learning!M5 -> Delta | M4: =RAVLT_Learning!N5 -> Percentile rank | O4: Abs diff delta | P4: Percentile
L5: =TMTB!M6 -> -1.632027 | M5: =TMTB!N6 -> 0 | O5: =ABS(L5-TMTB!$C$34) -> 1.5199847 | P5: =M5 -> 0
A6: Not assuming homoscedasticity, residual std.error per group: | L6: =TMTB!M7 -> -1.5705501 | M6: =TMTB!N7 -> 0.1 | O6: =ABS(L6-TMTB!$C$34) -> 1.4585078 | P6: =M6 -> 0.1
L7: =TMTB!M8 -> -1.5090731 | M7: =TMTB!N8 -> 0.2 | O7: =ABS(L7-TMTB!$C$34) -> 1.3970308 | P7: =M7 -> 0.2
A8: Predicted score: | B8: =TMTB!C27 -> -16.515674
L9: =TMTB!M9 -> -1.4546968 | M9: =TMTB!N9 -> 0.3 | O9: =ABS(L9-TMTB!$C$34) -> 1.3426545 | P9: =M9 -> 0.3
B10: =RAVLT_Learning!J10 -> Residual variance | C10: =RAVLT_Learning!I10 -> Predicted test score | L10: =TMTB!M10 -> -1.4402447 | M10: =TMTB!N10 -> 0.4 | O10: =ABS(L10-TMTB!$C$34) -> 1.3282024 | P10: =M10 -> 0.4
B11: =TMTB!J11 -> 0 | C11: =TMTB!I11 -> 0 | L11: =TMTB!M11 -> -1.4257926 | M11: =TMTB!N11 -> 0.5 | O11: =ABS(L11-TMTB!$C$34) -> 1.3137504 | P11: =M11 -> 0.5
B12: =TMTB!J12 -> 0 | C12: =TMTB!I12 -> 0 | L12: =TMTB!M12 -> -1.410221 | M12: =TMTB!N12 -> 0.6 | O12: =ABS(L12-TMTB!$C$34) -> 1.2981787 | P12: =M12 -> 0.6
B13: =TMTB!J13 -> 0 | C13: =TMTB!I13 -> 0 | L13: =TMTB!M13 -> -1.3920616 | M13: =TMTB!N13 -> 0.7 | O13: =ABS(L13-TMTB!$C$34) -> 1.2800194 | P13: =M13 -> 0.7
B14: =TMTB!J14 -> 0 | C14: =TMTB!I14 -> 0 | L14: =TMTB!M14 -> -1.3739023 | M14: =TMTB!N14 -> 0.8 | O14: =ABS(L14-TMTB!$C$34) -> 1.2618601 | P14: =M14 -> 0.8
B15: =TMTB!J15 -> 0 | C15: =TMTB!I15 -> 0 | L15: =TMTB!M15 -> -1.3637863 | M15: =TMTB!N15 -> 0.9 | O15: =ABS(L15-TMTB!$C$34) -> 1.2517441 | P15: =M15 -> 0.9
B16: =TMTB!J16 -> 0 | C16: =TMTB!I16 -> 0 | L16: =TMTB!M16 -> -1.363383 | M16: =TMTB!N16 -> 1 | O16: =ABS(L16-TMTB!$C$34) -> 1.2513408 | P16: =M16 -> 1
B17: =TMTB!J17 -> 0 | C17: =TMTB!I17 -> 0 | L17: =TMTB!M17 -> -1.3629797 | M17: =TMTB!N17 -> 1.1 | O17: =ABS(L17-TMTB!$C$34) -> 1.2509375 | P17: =M17 -> 1.1
B18: =TMTB!J18 -> 0 | C18: =TMTB!I18 -> 0 | L18: =TMTB!M18 -> -1.3554729 | M18: =TMTB!N18 -> 1.2 | O18: =ABS(L18-TMTB!$C$34) -> 1.2434307 | P18: =M18 -> 1.2
B19: =TMTB!J19 -> 0 | C19: =TMTB!I19 -> 0 | L19: =TMTB!M19 -> -1.3433087 | M19: =TMTB!N19 -> 1.3 | O19: =ABS(L19-TMTB!$C$34) -> 1.2312664 | P19: =M19 -> 1.3
B20: =TMTB!J20 -> 0 | C20: =TMTB!I20 -> 0 | E20: Residual variance | G20: {=INDEX(B11:B22,MATCH(MIN(ABS(C11:C22-B8)),ABS(C11:C22-B8),0))} -> 0 | L20: =TMTB!M20 -> -1.3311444 | M20: =TMTB!N20 -> 1.4 | O20: =ABS(L20-TMTB!$C$34) -> 1.2191022 | P20: =M20 -> 1.4
B21: =TMTB!J21 -> 0 | C21: =TMTB!I21 -> 0 | E21: Residual std. Error | G21: =SQRT(G20) -> 0 | L21: =TMTB!M21 -> -1.3274228 | M21: =TMTB!N21 -> 1.5 | O21: =ABS(L21-TMTB!$C$34) -> 1.2153805 | P21: =M21 -> 1.5
B22: =TMTB!J22 -> 0 | C22: =TMTB!I22 -> 0 | L22: =TMTB!M22 -> -1.326441 | M22: =TMTB!N22 -> 1.6 | O22: =ABS(L22-TMTB!$C$34) -> 1.2143988 | P22: =M22 -> 1.6
E23: Formula, see: | F23: https://www.excel-easy.com/examples/closest-match.html | L23: =TMTB!M23 -> -1.3254593 | M23: =TMTB!N23 -> 1.7 | O23: =ABS(L23-TMTB!$C$34) -> 1.213417 | P23: =M23 -> 1.7
L24: =TMTB!M24 -> -1.3047685 | M24: =TMTB!N24 -> 1.8 | O24: =ABS(L24-TMTB!$C$34) -> 1.1927263 | P24: =M24 -> 1.8
A25: Not assuming homoscedasticity, variance function | L25: =TMTB!M25 -> -1.2820325 | M25: =TMTB!N25 -> 1.9 | O25: =ABS(L25-TMTB!$C$34) -> 1.1699903 | P25: =M25 -> 1.9
L26: =TMTB!M26 -> -1.2604238 | M26: =TMTB!N26 -> 2 | O26: =ABS(L26-TMTB!$C$34) -> 1.1483815 | P26: =M26 -> 2
A27: =RAVLT_Learning!I26 | B27: =RAVLT_Learning!J26 -> Estimate | C27: X | D27: Beta x X | L27: =TMTB!M27 -> -1.2574719 | M27: =TMTB!N27 -> 2.1 | O27: =ABS(L27-TMTB!$C$34) -> 1.1454296 | P27: =M27 -> 2.1
A28: =TMTB!I27 -> (Intercept) | B28: =TMTB!J27 -> 13730.003 | C28: 1 | D28: =B28*C28 -> 13730.003 | L28: =TMTB!M28 -> -1.25452 | M28: =TMTB!N28 -> 2.2 | O28: =ABS(L28-TMTB!$C$34) -> 1.1424777 | P28: =M28 -> 2.2
A29: =TMTB!I28 -> Pred.Y | B29: =TMTB!J28 -> -413.0929 | C29: =B8 -> -16.515674 | D29: =B29*C29 -> 6822.5075 | L29: =TMTB!M29 -> -1.2508314 | M29: =TMTB!N29 -> 2.3 | O29: =ABS(L29-TMTB!$C$34) -> 1.1387891 | P29: =M29 -> 2.3
A30: =TMTB!I29 -> Pred.Y.2 | B30: =TMTB!J29 -> 4.1126815 | C30: =B8^2 -> 272.76747 | D30: =B30*C30 -> 1121.8058 | L30: =TMTB!M30 -> -1.2443372 | M30: =TMTB!N30 -> 2.4 | O30: =ABS(L30-TMTB!$C$34) -> 1.1322949 | P30: =M30 -> 2.4
A31: =TMTB!I30 -> Pred.Y.3 | B31: =TMTB!J30 -> -0.012018306 | C31: =B8^3 -> -4504.9386 | D31: =B31*C31 -> 54.141732 | L31: =TMTB!M31 -> -1.237843 | M31: =TMTB!N31 -> 2.5 | O31: =ABS(L31-TMTB!$C$34) -> 1.1258007 | P31: =M31 -> 2.5
A32: =TMTB!I31 -> 0 | B32: =TMTB!J31 -> 0 | C32: =B8^4 -> 74402.095 | D32: =B32*C32 -> 0 | L32: =TMTB!M32 -> -1.2320095 | M32: =TMTB!N32 -> 2.6 | O32: =ABS(L32-TMTB!$C$34) -> 1.1199672 | P32: =M32 -> 2.6
A33: =TMTB!I32 -> 0 | B33: =TMTB!J32 -> 0 | C33: =B8^5 -> -1228800.7 | D33: =B33*C33 -> 0 | L33: =TMTB!M33 -> -1.2273559 | M33: =TMTB!N33 -> 2.7 | O33: =ABS(L33-TMTB!$C$34) -> 1.1153137 | P33: =M33 -> 2.7
G34: =SQRT(D35) -> 147.40576 | L34: =TMTB!M34 -> -1.2227024 | M34: =TMTB!N34 -> 2.8 | O34: =ABS(L34-TMTB!$C$34) -> 1.1106601 | P34: =M34 -> 2.8
B35: Predicted VARIANCE | D35: =SUM(D28:D34) -> 21728.458 | L35: =TMTB!M35 -> -1.2201875 | M35: =TMTB!N35 -> 2.9 | O35: =ABS(L35-TMTB!$C$34) -> 1.1081453 | P35: =M35 -> 2.9
L36: =TMTB!M36 -> -1.2197277 | M36: =TMTB!N36 -> 3 | O36: =ABS(L36-TMTB!$C$34) -> 1.1076854 | P36: =M36 -> 3
A37: Checks | L37: =TMTB!M37 -> -1.2192679 | M37: =TMTB!N37 -> 3.1 | O37: =ABS(L37-TMTB!$C$34) -> 1.1072256 | P37: =M37 -> 3.1
A38: Overall resid std error entered | D38: =IF(G3>0, 1, 0) -> 0 | G38: Res. Std error | I38: =IF(D41=1, G3+G21+G34, ) -> 147.40576 | L38: =TMTB!M38 -> -1.212497 | M38: =TMTB!N38 -> 3.2 | O38: =ABS(L38-TMTB!$C$34) -> 1.1004547 | P38: =M38 -> 3.2
A39: Resid std per group | D39: =IF(G21>0, 1, 0) -> 0 | I39: =IF(D41=1, " ", "ERROR!") | L39: =TMTB!M39 -> -1.2024889 | M39: =TMTB!N39 -> 3.3 | O39: =ABS(L39-TMTB!$C$34) -> 1.0904467 | P39: =M39 -> 3.3
A40: Variance function | D40: =IF(G34>0, 1, 0) -> 1 | L40: =TMTB!M40 -> -1.1924809 | M40: =TMTB!N40 -> 3.4 | O40: =ABS(L40-TMTB!$C$34) -> 1.0804386 | P40: =M40 -> 3.4
C41: Som | D41: =SUM(D38:D40) -> 1 | E41: (check should be 1 to be OK) | L41: =TMTB!M41 -> -1.1766859 | M41: =TMTB!N41 -> 3.5 | O41: =ABS(L41-TMTB!$C$34) -> 1.0646436 | P41: =M41 -> 3.5
...

Sheet TMTA
B1: ONLY MAKE CHANGES IN THE GREY HIGHLIGHTED CELLS | I1: =SD_PERC_TMTA!A42
A3: 1 | B3: COPY-PASTE FINAL STAGE 1 MEAN PREDICTION FUNCTION HERE: | H3: 2 | I3: COPY-PASTE FINAL STAGE 1 VARIANCE PREDICTION FUNCTION HERE: | L3: 3 | M3: COPY-PASTE PERCENTILE RANKS DELTA HERE:
C5: Estimate | H5: A | I5: Assuming homoscedasticity | M5: Delta | N5: Percentile rank
B6: (Intercept) | C6: 37.645081 | I6: Residual variance | J6: 187.00924 | M6: -2.030783 | N6: 0
B7: ageC | C7: 0.69112692 | M7: -1.9979107 | N7: 0.1
M8: -1.9650383 | N8: 0.2
H9: B | I9: Not assuming homoscedasticity, prediction-specific residual variances: | M9: -1.9259069 | N9: 0.3
I10: Predicted test score | J10: Residual variance | M10: -1.8790939 | N10: 0.4
M11: -1.8322808 | N11: 0.5
M12: -1.7722463 | N12: 0.6
M13: -1.7107094 | N13: 0.7
M14: -1.6659906 | N14: 0.8
M15: -1.6529296 | N15: 0.9
M16: -1.6398685 | N16: 1
M17: -1.6301562 | N17: 1.1
M18: -1.6213025 | N18: 1.2
M19: -1.6136944 | N19: 1.3
M20: -1.6099273 | N20: 1.4
M21: -1.6061602 | N21: 1.5
M22: -1.5938743 | N22: 1.6
... M24: -1.5637775 | N24: 1.8
H25: C | I25: Not assuming homoscedasticity, continuous variance prediction function: | M25: -1.561674 | N25: 1.9
J26: Estimate | M26: -1.5595706 | N26: 2
A27: 4 | B27: Predicted test score: | C27: =C6+(C7*('Normative data'!C6-71.28)) -> -11.618446 | M27: -1.5549773 | N27: 2.1
B28: [SPECIFY THE APPROPRIATE FORMULA IN CELL B27 TO COMPUTE | M28: -1.5486668 | N28: 2.2
B29: THE PREDICTED TEST SCORE BASED ON THE INPUT PROVIDED | M29: -1.5425281 | N29: 2.3
B30: IN SHEET 1 (E.G. SPECIFIED GENDER) + COPY-PASTED STAGE 1 MODEL] | M30: -1.5404247 | N30: 2.4
M31: -1.5383212 | N31: 2.5
M32: -1.5370324 | N32: 2.6
B33: Computed residual: | C33: ='Normative data'!C16-TMTA!C27 -> 11.618446 | M33: -1.5365922 | N33: 2.7
B34: Std. Residual: | C34: =-(C33/SD_PERC_TMTA!I38) -> -0.84960395 | I34: Residual Std.Error to be used: | J34: =SD_PERC_TMTA!I38 -> 13.675132 | M34: -1.536152 | N34: 2.8
M35: -1.5302009 | N35: 2.9
M36: -1.5238905 | N36: 3
M37: -1.514792 | N37: 3.1
M38: -1.5012911 | N38: 3.2
M39: -1.4877902 | N39: 3.3
M40: -1.4746577 | N40: 3.4
M41: -1.461597 | N41: 3.5
M42: -1.451066 | N42: 3.6
M43: -1.4468591 | N43: 3.7
...

Sheet SD_PERC_TMTA
A1: Determine SD(residual) to use; DO NOT MAKE CHANGES HERE | L1: Determine percentile
A3: Assuming homoscedasticity | G3: =SQRT(TMTA!J6) -> 13.675132
L4: =RAVLT_Learning!M5 -> Delta | M4: =RAVLT_Learning!N5 -> Percentile rank | O4: Abs diff delta | P4: Percentile
L5: =TMTA!M6 -> -2.030783 | M5: =TMTA!N6 -> 0 | O5: =ABS(L5-TMTA!$C$34) -> 1.181179 | P5: =M5 -> 0
A6: Not assuming homoscedasticity, residual std.error per group: | L6: =TMTA!M7 -> -1.9979107 | M6: =TMTA!N7 -> 0.1 | O6: =ABS(L6-TMTA!$C$34) -> 1.1483067 | P6: =M6 -> 0.1
L7: =TMTA!M8 -> -1.9650383 | M7: =TMTA!N8 -> 0.2 | O7: =ABS(L7-TMTA!$C$34) -> 1.1154344 | P7: =M7 -> 0.2
A8: Predicted score: | B8: =TMTA!C27 -> -11.618446
L9: =TMTA!M9 -> -1.9259069 | M9: =TMTA!N9 -> 0.3 | O9: =ABS(L9-TMTA!$C$34) -> 1.076303 | P9: =M9 -> 0.3
B10: =RAVLT_Learning!J10 -> Residual variance | C10: =RAVLT_Learning!I10 -> Predicted test score | L10: =TMTA!M10 -> -1.8790939 | M10: =TMTA!N10 -> 0.4 | O10: =ABS(L10-TMTA!$C$34) -> 1.0294899 | P10: =M10 -> 0.4
B11: =TMTA!J11 -> 0 | C11: =TMTA!I11 -> 0 | L11: =TMTA!M11 -> -1.8322808 | M11: =TMTA!N11 -> 0.5 | O11: =ABS(L11-TMTA!$C$34) -> 0.98267689 | P11: =M11 -> 0.5
B12: =TMTA!J12 -> 0 | C12: =TMTA!I12 -> 0 | L12: =TMTA!M12 -> -1.7722463 | M12: =TMTA!N12 -> 0.6 | O12: =ABS(L12-TMTA!$C$34) -> 0.92264238 | P12: =M12 -> 0.6
B13: =TMTA!J13 -> 0 | C13: =TMTA!I13 -> 0 | L13: =TMTA!M13 -> -1.7107094 | M13: =TMTA!N13 -> 0.7 | O13: =ABS(L13-TMTA!$C$34) -> 0.86110544 | P13: =M13 -> 0.7
B14: =TMTA!J14 -> 0 | C14: =TMTA!I14 -> 0 | L14: =TMTA!M14 -> -1.6659906 | M14: =TMTA!N14 -> 0.8 | O14: =ABS(L14-TMTA!$C$34) -> 0.81638666 | P14: =M14 -> 0.8
B15: =TMTA!J15 -> 0 | C15: =TMTA!I15 -> 0 | L15: =TMTA!M15 -> -1.6529296 | M15: =TMTA!N15 -> 0.9 | O15: =ABS(L15-TMTA!$C$34) -> 0.80332562 | P15: =M15 -> 0.9
B16: =TMTA!J16 -> 0 | C16: =TMTA!I16 -> 0 | L16: =TMTA!M16 -> -1.6398685 | M16: =TMTA!N16 -> 1 | O16: =ABS(L16-TMTA!$C$34) -> 0.79026457 | P16: =M16 -> 1
B17: =TMTA!J17 -> 0 | C17: =TMTA!I17 -> 0 | L17: =TMTA!M17 -> -1.6301562 | M17: =TMTA!N17 -> 1.1 | O17: =ABS(L17-TMTA!$C$34) -> 0.78055222 | P17: =M17 -> 1.1
B18: =TMTA!J18 -> 0 | C18: =TMTA!I18 -> 0 | L18: =TMTA!M18 -> -1.6213025 | M18: =TMTA!N18 -> 1.2 | O18: =ABS(L18-TMTA!$C$34) -> 0.7716985 | P18: =M18 -> 1.2
B19: =TMTA!J19 -> 0 | C19: =TMTA!I19 -> 0 | L19: =TMTA!M19 -> -1.6136944 | M19: =TMTA!N19 -> 1.3 | O19: =ABS(L19-TMTA!$C$34) -> 0.76409049 | P19: =M19 -> 1.3
B20: =TMTA!J20 -> 0 | C20: =TMTA!I20 -> 0 | E20: Residual variance | G20: {=INDEX(B11:B22,MATCH(MIN(ABS(C11:C22-B8)),ABS(C11:C22-B8),0))} -> 0 | L20: =TMTA!M20 -> -1.6099273 | M20: =TMTA!N20 -> 1.4 | O20: =ABS(L20-TMTA!$C$34) -> 0.76032337 | P20: =M20 -> 1.4
B21: =TMTA!J21 -> 0 | C21: =TMTA!I21 -> 0 | E21: Residual std. Error | G21: =SQRT(G20) -> 0 | L21: =TMTA!M21 -> -1.6061602 | M21: =TMTA!N21 -> 1.5 | O21: =ABS(L21-TMTA!$C$34) -> 0.75655625 | P21: =M21 -> 1.5
B22: =TMTA!J22 -> 0 | C22: =TMTA!I22 -> 0 | L22: =TMTA!M22 -> -1.5938743 | M22: =TMTA!N22 -> 1.6 | O22: =ABS(L22-TMTA!$C$34) -> 0.74427036 | P22: =M22 -> 1.6
E23: Formula, see: | F23: https://www.excel-easy.com/examples/closest-match.html | L23: =TMTA!M23 -> -1.5778301 | M23: =TMTA!N23 -> 1.7 | O23: =ABS(L23-TMTA!$C$34) -> 0.72822619 | P23: =M23 -> 1.7
L24: =TMTA!M24 -> -1.5637775 | M24: =TMTA!N24 -> 1.8 | O24: =ABS(L24-TMTA!$C$34) -> 0.71417355 | P24: =M24 -> 1.8
A25: Not assuming homoscedasticity, variance function | L25: =TMTA!M25 -> -1.561674 | M25: =TMTA!N25 -> 1.9 | O25: =ABS(L25-TMTA!$C$34) -> 0.71207008 | P25: =M25 -> 1.9
L26: =TMTA!M26 -> -1.5595706 | M26: =TMTA!N26 -> 2 | O26: =ABS(L26-TMTA!$C$34) -> 0.70996661 | P26: =M26 -> 2
A27: =RAVLT_Learning!I26 | B27: =RAVLT_Learning!J26 -> Estimate | C27: X | D27: Beta x X | L27: =TMTA!M27 -> -1.5549773 | M27: =TMTA!N27 -> 2.1 | O27: =ABS(L27-TMTA!$C$34) -> 0.70537331 | P27: =M27 -> 2.1
A28: =TMTA!I27 -> 0 | B28: =TMTA!J27 -> 0 | C28: 1 | D28: =B28*C28 -> 0 | L28: =TMTA!M28 -> -1.5486668 | M28: =TMTA!N28 -> 2.2 | O28: =ABS(L28-TMTA!$C$34) -> 0.6990629 | P28: =M28 -> 2.2
A29: =TMTA!I28 -> 0 | B29: =TMTA!J28 -> 0 | C29: =B8 -> -11.618446 | D29: =B29*C29 -> 0 | L29: =TMTA!M29 -> -1.5425281 | M29: =TMTA!N29 -> 2.3 | O29: =ABS(L29-TMTA!$C$34) -> 0.69292419 | P29: =M29 -> 2.3
A30: =TMTA!I29 -> 0 | B30: =TMTA!J29 -> 0 | C30: =B8^2 -> 134.98829 | D30: =B30*C30 -> 0 | L30: =TMTA!M30 -> -1.5404247 | M30: =TMTA!N30 -> 2.4 | O30: =ABS(L30-TMTA!$C$34) -> 0.69082072 | P30: =M30 -> 2.4
A31: =TMTA!I30 -> 0 | B31: =TMTA!J30 -> 0 | C31: =B8^3 -> -1568.3542 | D31: =B31*C31 -> 0 | L31: =TMTA!M31 -> -1.5383212 | M31: =TMTA!N31 -> 2.5 | O31: =ABS(L31-TMTA!$C$34) -> 0.68871725 | P31: =M31 -> 2.5
A32: =TMTA!I31 -> 0 | B32: =TMTA!J31 -> 0 | C32: =B8^4 -> 18221.839 | D32: =B32*C32 -> 0 | L32: =TMTA!M32 -> -1.5370324 | M32: =TMTA!N32 -> 2.6 | O32: =ABS(L32-TMTA!$C$34) -> 0.68742843 | P32: =M32 -> 2.6
A33: =TMTA!I32 -> 0 | B33: =TMTA!J32 -> 0 | C33: =B8^5 -> -211709.45 | D33: =B33*C33 -> 0 | L33: =TMTA!M33 -> -1.5365922 | M33: =TMTA!N33 -> 2.7 | O33: =ABS(L33-TMTA!$C$34) -> 0.68698822 | P33: =M33 -> 2.7
G34: =SQRT(D35) -> 0 | L34: =TMTA!M34 -> -1.536152 | M34: =TMTA!N34 -> 2.8 | O34: =ABS(L34-TMTA!$C$34) -> 0.686548 | P34: =M34 -> 2.8
B35: Predicted VARIANCE | D35: =SUM(D28:D34) -> 0 | L35: =TMTA!M35 -> -1.5302009 | M35: =TMTA!N35 -> 2.9 | O35: =ABS(L35-TMTA!$C$34) -> 0.68059698 | P35: =M35 -> 2.9
L36: =TMTA!M36 -> -1.5238905 | M36: =TMTA!N36 -> 3 | O36: =ABS(L36-TMTA!$C$34) -> 0.67428657 | P36: =M36 -> 3
A37: Checks | L37: =TMTA!M37 -> -1.514792 | M37: =TMTA!N37 -> 3.1 | O37: =ABS(L37-TMTA!$C$34) -> 0.66518802 | P37: =M37 -> 3.1
A38: Overall resid std error entered | D38: =IF(G3>0, 1, 0) -> 1 | G38: Res. Std error | I38: =IF(D41=1, G3+G21+G34, ) -> 13.675132 | L38: =TMTA!M38 -> -1.5012911 | M38: =TMTA!N38 -> 3.2 | O38: =ABS(L38-TMTA!$C$34) -> 0.65168714 | P38: =M38 -> 3.2
A39: Resid std per group | D39: =IF(G21>0, 1, 0) -> 0 | I39: =IF(D41=1, " ", "ERROR!") | L39: =TMTA!M39 -> -1.4877902 | M39: =TMTA!N39 -> 3.3 | O39: =ABS(L39-TMTA!$C$34) -> 0.63818627 | P39: =M39 -> 3.3
A40: Variance function | D40: =IF(G34>0, 1, 0) -> 0 | L40: =TMTA!M40 -> -1.4746577 | M40: =TMTA!N40 -> 3.4 | O40: =ABS(L40-TMTA!$C$34) -> 0.62505374 | P40: =M40 -> 3.4
C41: Som | D41: =SUM(D38:D40) -> 1 | E41: (check should be 1 to be OK) | L41: =TMTA!M41 -> -1.461597 | M41: =TMTA!N41 -> 3.5 | O41: =ABS(L41-TMTA!$C$34) -> 0.61199309 | P41: =M41 -> 3.5
...

Sheet DigDir
B1: ONLY MAKE CHANGES IN THE GREY HIGHLIGHTED CELLS | I1: =SD_PERC_DigDir!A42
A3: 1 | B3: COPY-PASTE FINAL STAGE 1 MEAN PREDICTION FUNCTION HERE: | H3: 2 | I3: COPY-PASTE FINAL STAGE 1 VARIANCE PREDICTION FUNCTION HERE: | L3: 3 | M3: COPY-PASTE PERCENTILE RANKS DELTA HERE:
C5: Estimate | H5: A | I5: Assuming homoscedasticity | M5: Delta | N5: Percentile rank
B6: (Intercept) | C6: 5.2287602 | I6: Residual variance | J6: 1.083504 | M6: -2.294671 | N6: 0
B7: years_education | C7: 0.057989859 | M7: -2.294671 | N7: 0.1
M8: -2.294671 | N8: 0.2
H9: B | I9: Not assuming homoscedasticity, prediction-specific residual variances: | M9: -2.2887657 | N9: 0.3
I10: Predicted test score | J10: Residual variance | M10: -2.2496569 | N10: 0.4
M11: -2.2105481 | N11: 0.5
M12: -2.18325 | N12: 0.6
M13: -2.18325 | N13: 0.7
M14: -2.18325 | N14: 0.8
M15: -2.18325 | N15: 0.9
M16: -2.18325 | N16: 1
M17: -2.18325 | N17: 1.1
M18: -2.1714395 | N18: 1.2
M19: -2.1518853 | N19: 1.3
M20: -2.1323311 | N20: 1.4
M21: -2.12754 | N21: 1.5
M22: -2.12754 | N22: 1.6
... M24: -2.1098239 | N24: 1.8
H25: C | I25: Not assuming homoscedasticity, continuous variance prediction function: | M25: -2.0902693 | N25: 1.9
J26: Estimate | M26: -2.071829 | N26: 2
A27: 4 | B27: Predicted test score: | C27: =C6+(C7*('Normative data'!C8)) -> 5.2287602 | M27: -2.071829 | N27: 2.1
B28: [SPECIFY THE APPROPRIATE FORMULA IN CELL B27 TO COMPUTE | M28: -2.071829 | N28: 2.2
B29: THE PREDICTED TEST SCORE BASED ON THE INPUT PROVIDED | M29: -2.0677622 | N29: 2.3
B30: IN SHEET 1 (E.G. SPECIFIED GENDER) + COPY-PASTED STAGE 1 MODEL] | M30: -2.048208 | N30: 2.4
M31: -2.0286538 | N31: 2.5
M32: -2.016119 | N32: 2.6
B33: Computed residual: | C33: ='Normative data'!C14-DigDir!C27 -> -5.2287602 | M33: -2.016119 | N33: 2.7
B34: Std. Residual: | C34: =C33/SD_PERC_DigDir!I38 -> -5.0232346 | I34: Residual Std.Error to be used: | J34: =SD_PERC_DigDir!I38 -> 1.040915 | M34: -2.016119 | N34: 2.8
M35: -2.016119 | N35: 2.9
M36: -2.016119 | N36: 3
M37: -2.016119 | N37: 3.1
M38: -2.003194 | N38: 3.2
M39: -1.9836395 | N39: 3.3
M40: -1.9640849 | N40: 3.4
M41: -1.9445304 | N41: 3.5
M42: -1.9249758 | N42: 3.6
M43: -1.9054212 | N43: 3.7
...

Sheet DigInv
B1: ONLY MAKE CHANGES IN THE GREY HIGHLIGHTED CELLS | I1: =SD_PERC_DigInv!A42
A3: 1 | B3: COPY-PASTE FINAL STAGE 1 MEAN PREDICTION FUNCTION HERE: | H3: 2 | I3: COPY-PASTE FINAL STAGE 1 VARIANCE PREDICTION FUNCTION HERE: | L3: 3 | M3: COPY-PASTE PERCENTILE RANKS DELTA HERE:
C5: Estimate | H5: A | I5: Assuming homoscedasticity | M5: Delta | N5: Percentile rank
B6: (Intercept) | C6: 3.7683509 | I6: Residual variance | M6: -2.747706 | N6: 0
B7: ageC | C7: -0.013251911 | M7: -2.3647201 | N7: 0.1
B8: years_education | C8: 0.052621479 | M8: -1.9817341 | N8: 0.2
H9: B | I9: Not assuming homoscedasticity, prediction-specific residual variances: | M9: -1.6565685 | N9: 0.3
I10: Predicted test score | J10: Residual variance | M10: -1.6565057 | N10: 0.4
M11: -1.6564429 | N11: 0.5
M12: -1.6563973 | N12: 0.6
M13: -1.6563917 | N13: 0.7
M14: -1.6563861 | N14: 0.8
M15: -1.6563423 | N15: 0.9
M16: -1.6562524 | N16: 1
M17: -1.6561626 | N17: 1.1
M18: -1.6559958 | N18: 1.2
M19: -1.6557785 | N19: 1.3
M20: -1.6555612 | N20: 1.4
M21: -1.655508 | N21: 1.5
M22: -1.655508 | N22: 1.6
... M24: -1.6553426 | N24: 1.8
H25: C | I25: Not assuming homoscedasticity, continuous variance prediction function: | M25: -1.6551601 | N25: 1.9
J26: Estimate | M26: -1.6549871 | N26: 2
A27: 4 | B27: Predicted test score: | C27: =C6+(C7*('Normative data'!C6-71.28))+(DigInv!C8*'Normative data'!C8) -> 4.7129471 | I27: (Intercept) | J27: -232.20989 | M27: -1.6549717 | N27: 2.1
B28: [SPECIFY THE APPROPRIATE FORMULA IN CELL B27 TO COMPUTE | I28: Pred.Y | J28: 162.49634 | M28: -1.6549562 | N28: 2.2
B29: THE PREDICTED TEST SCORE BASED ON THE INPUT PROVIDED | I29: Pred.Y.2 | J29: -37.908259 | M29: -1.6548812 | N29: 2.3
B30: IN SHEET 1 (E.G. SPECIFIED GENDER) + COPY-PASTED STAGE 1 MODEL] | I30: Pred.Y.3 | J30: 2.956833 | M30: -1.6545794 | N30: 2.4
M31: -1.6542775 | N31: 2.5
M32: -1.654084 | N32: 2.6
B33: Computed residual: | C33: ='Normative data'!C15-DigInv!C27 -> -4.7129471 | M33: -1.654084 | N33: 2.7
B34: Std. Residual: | C34: =C33/SD_PERC_DigInv!I38 -> -4.405079 | I34: Residual Std.Error to be used: | J34: =SD_PERC_DigInv!I38 -> 1.0698893 | M34: -1.654084 | N34: 2.8
M35: -1.6539098 | N35: 2.9
M36: -1.6535683 | N36: 3
M37: -1.6532268 | N37: 3.1
M38: -1.6528732 | N38: 3.2
M39: -1.6525134 | N39: 3.3
M40: -1.6521537 | N40: 3.4
M41: -1.6516645 | N41: 3.5
M42: -1.6511454 | N42: 3.6
M43: -1.6506262 | N43: 3.7
...

Sheet SD_PERC_DigDir
A1: Determine SD(residual) to use; DO NOT MAKE CHANGES HERE | L1: Determine percentile
A3: Assuming homoscedasticity | G3: =SQRT(DigDir!J6) -> 1.040915
L4: =RAVLT_Learning!M5 -> Delta | M4: =RAVLT_Learning!N5 -> Percentile rank | O4: Abs diff delta | P4: Percentile
L5: =DigDir!M6 -> -2.294671 | M5: =DigDir!N6 -> 0 | O5: =ABS(L5-DigDir!$C$34) -> 2.7285636 | P5: =M5 -> 0
A6: Not assuming homoscedasticity, residual std.error per group: | L6: =DigDir!M7 -> -2.294671 | M6: =DigDir!N7 -> 0.1 | O6: =ABS(L6-DigDir!$C$34) -> 2.7285636 | P6: =M6 -> 0.1
L7: =DigDir!M8 -> -2.294671 | M7: =DigDir!N8 -> 0.2 | O7: =ABS(L7-DigDir!$C$34) -> 2.7285636 | P7: =M7 -> 0.2
A8: Predicted score: | B8: =DigDir!C27 -> 5.2287602
L9: =DigDir!M9 -> -2.2887657 | M9: =DigDir!N9 -> 0.3 | O9: =ABS(L9-DigDir!$C$34) -> 2.7344689 | P9: =M9 -> 0.3
B10: =RAVLT_Learning!J10 -> Residual variance | C10: =RAVLT_Learning!I10 -> Predicted test score | L10: =DigDir!M10 -> -2.2496569 | M10: =DigDir!N10 -> 0.4 | O10: =ABS(L10-DigDir!$C$34) -> 2.7735776 | P10: =M10 -> 0.4
B11: =DigDir!J11 -> 0 | C11: =DigDir!I11 -> 0 | L11: =DigDir!M11 -> -2.2105481 | M11: =DigDir!N11 -> 0.5 | O11: =ABS(L11-DigDir!$C$34) -> 2.8126864 | P11: =M11 -> 0.5
B12: =DigDir!J12 -> 0 | C12: =DigDir!I12 -> 0 | L12: =DigDir!M12 -> -2.18325 | M12: =DigDir!N12 -> 0.6 | O12: =ABS(L12-DigDir!$C$34) -> 2.8399846 | P12: =M12 -> 0.6
B13: =DigDir!J13 -> 0 | C13: =DigDir!I13 -> 0 | L13: =DigDir!M13 -> -2.18325 | M13: =DigDir!N13 -> 0.7 | O13: =ABS(L13-DigDir!$C$34) -> 2.8399846 | P13: =M13 -> 0.7
B14: =DigDir!J14 -> 0 | C14: =DigDir!I14 -> 0 | L14: =DigDir!M14 -> -2.18325 | M14: =DigDir!N14 -> 0.8 | O14: =ABS(L14-DigDir!$C$34) -> 2.8399846 | P14: =M14 -> 0.8
B15: =DigDir!J15 -> 0 | C15: =DigDir!I15 -> 0 | L15: =DigDir!M15 -> -2.18325 | M15: =DigDir!N15 -> 0.9 | O15: =ABS(L15-DigDir!$C$34) -> 2.8399846 | P15: =M15 -> 0.9
B16: =DigDir!J16 -> 0 | C16: =DigDir!I16 -> 0 | L16: =DigDir!M16 -> -2.18325 | M16: =DigDir!N16 -> 1 | O16: =ABS(L16-DigDir!$C$34) -> 2.8399846 | P16: =M16 -> 1
B17: =DigDir!J17 -> 0 | C17: =DigDir!I17 -> 0 | L17: =DigDir!M17 -> -2.18325 | M17: =DigDir!N17 -> 1.1 | O17: =ABS(L17-DigDir!$C$34) -> 2.8399846 | P17: =M17 -> 1.1
B18: =DigDir!J18 -> 0 | C18: =DigDir!I18 -> 0 | L18: =DigDir!M18 -> -2.1714395 | M18: =DigDir!N18 -> 1.2 | O18: =ABS(L18-DigDir!$C$34) -> 2.8517951 | P18: =M18 -> 1.2
B19: =DigDir!J19 -> 0 | C19: =DigDir!I19 -> 0 | L19: =DigDir!M19 -> -2.1518853 | M19: =DigDir!N19 -> 1.3 | O19: =ABS(L19-DigDir!$C$34) -> 2.8713493 | P19: =M19 -> 1.3
B20: =DigDir!J20 -> 0 | C20: =DigDir!I20 -> 0 | E20: Residual variance | G20: {=INDEX(B11:B22,MATCH(MIN(ABS(C11:C22-B8)),ABS(C11:C22-B8),0))} -> 0 | L20: =DigDir!M20 -> -2.1323311 | M20: =DigDir!N20 -> 1.4 | O20: =ABS(L20-DigDir!$C$34) -> 2.8909035 | P20: =M20 -> 1.4
B21: =DigDir!J21 -> 0 | C21: =DigDir!I21 -> 0 | E21: Residual std. Error | G21: =SQRT(G20) -> 0 | L21: =DigDir!M21 -> -2.12754 | M21: =DigDir!N21 -> 1.5 | O21: =ABS(L21-DigDir!$C$34) -> 2.8956946 | P21: =M21 -> 1.5
B22: =DigDir!J22 -> 0 | C22: =DigDir!I22 -> 0 | L22: =DigDir!M22 -> -2.12754 | M22: =DigDir!N22 -> 1.6 | O22: =ABS(L22-DigDir!$C$34) -> 2.8956946 | P22: =M22 -> 1.6
E23: Formula, see: | F23: https://www.excel-easy.com/examples/closest-match.html | L23: =DigDir!M23 -> -2.12754 | M23: =DigDir!N23 -> 1.7 | O23: =ABS(L23-DigDir!$C$34) -> 2.8956946 | P23: =M23 -> 1.7
L24: =DigDir!M24 -> -2.1098239 | M24: =DigDir!N24 -> 1.8 | O24: =ABS(L24-DigDir!$C$34) -> 2.9134107 | P24: =M24 -> 1.8
A25: Not assuming homoscedasticity, variance function | L25: =DigDir!M25 -> -2.0902693 | M25: =DigDir!N25 -> 1.9 | O25: =ABS(L25-DigDir!$C$34) -> 2.9329652 | P25: =M25 -> 1.9
L26: =DigDir!M26 -> -2.071829 | M26: =DigDir!N26 -> 2 | O26: =ABS(L26-DigDir!$C$34) -> 2.9514056 | P26: =M26 -> 2
A27: =RAVLT_Learning!I26 | B27: =RAVLT_Learning!J26 -> Estimate | C27: X | D27: Beta x X | L27: =DigDir!M27 -> -2.071829 | M27: =DigDir!N27 -> 2.1 | O27: =ABS(L27-DigDir!$C$34) -> 2.9514056 | P27: =M27 -> 2.1
L28: =DigDir!M28 -> -2.071829 | M28: =DigDir!N28 -> 2.2 | O28: =ABS(L28-DigDir!$C$34) -> 2.9514056 | P28: =M28 -> 2.2
L29: =DigDir!M29 -> -2.0677622 | M29: =DigDir!N29 -> 2.3 | O29: =ABS(L29-DigDir!$C$34) -> 2.9554724 | P29: =M29 -> 2.3
L30: =DigDir!M30 -> -2.048208 | M30: =DigDir!N30 -> 2.4 | O30: =ABS(L30-DigDir!$C$34) -> 2.9750266 | P30: =M30 -> 2.4
L31: =DigDir!M31 -> -2.0286538 | M31: =DigDir!N31 -> 2.5 | O31: =ABS(L31-DigDir!$C$34) -> 2.9945808 | P31: =M31 -> 2.5
L32: =DigDir!M32 -> -2.016119 | M32: =DigDir!N32 -> 2.6 | O32: =ABS(L32-DigDir!$C$34) -> 3.0071156 | P32: =M32 -> 2.6
L33: =DigDir!M33 -> -2.016119 | M33: =DigDir!N33 -> 2.7 | O33: =ABS(L33-DigDir!$C$34) -> 3.0071156 | P33: =M33 -> 2.7
G34: =SQRT(D35) -> 0 | L34: =DigDir!M34 -> -2.016119 | M34: =DigDir!N34 -> 2.8 | O34: =ABS(L34-DigDir!$C$34) -> 3.0071156 | P34: =M34 -> 2.8
B35: Predicted VARIANCE | L35: =DigDir!M35 -> -2.016119 | M35: =DigDir!N35 -> 2.9 | O35: =ABS(L35-DigDir!$C$34) -> 3.0071156 | P35: =M35 -> 2.9
L36: =DigDir!M36 -> -2.016119 | M36: =DigDir!N36 -> 3 | O36: =ABS(L36-DigDir!$C$34) -> 3.0071156 | P36: =M36 -> 3
A37: Checks | L37: =DigDir!M37 -> -2.016119 | M37: =DigDir!N37 -> 3.1 | O37: =ABS(L37-DigDir!$C$34) -> 3.0071156 | P37: =M37 -> 3.1
A38: Overall resid std error entered | D38: =IF(G3>0, 1, 0) -> 1 | G38: Res. Std error | I38: =IF(D41=1, G3+G21+G34, ) -> 1.040915 | L38: =DigDir!M38 -> -2.003194 | M38: =DigDir!N38 -> 3.2 | O38: =ABS(L38-DigDir!$C$34) -> 3.0200405 | P38: =M38 -> 3.2
A39: Resid std per group | D39: =IF(G21>0, 1, 0) -> 0 | I39: =IF(D41=1, " ", "ERROR!") | L39: =DigDir!M39 -> -1.9836395 | M39: =DigDir!N39 -> 3.3 | O39: =ABS(L39-DigDir!$C$34) -> 3.0395951 | P39: =M39 -> 3.3
A40: Variance function | D40: =IF(G34>0, 1, 0) -> 0 | L40: =DigDir!M40 -> -1.9640849 | M40: =DigDir!N40 -> 3.4 | O40: =ABS(L40-DigDir!$C$34) -> 3.0591496 | P40: =M40 -> 3.4
C41: Som | D41: =SUM(D38:D40) -> 1 | E41: (check should be 1 to be OK) | L41: =DigDir!M41 -> -1.9445304 | M41: =DigDir!N41 -> 3.5 | O41: =ABS(L41-DigDir!$C$34) -> 3.0787042 | P41: =M41 -> 3.5
...

Sheet SD_PERC_DigInv
A1: Determine SD(residual) to use; DO NOT MAKE CHANGES HERE | L1: Determine percentile
A3: Assuming homoscedasticity | G3: =SQRT(DigInv!J6) -> 0
L4: =RAVLT_Learning!M5 -> Delta | M4: =RAVLT_Learning!N5 -> Percentile rank | O4: Abs diff delta | P4: Percentile
L5: =DigInv!M6 -> -2.747706 | M5: =DigInv!N6 -> 0 | O5: =ABS(L5-DigInv!$C$34) -> 1.657373 | P5: =M5 -> 0
A6: Not assuming homoscedasticity, residual std.error per group: | L6: =DigInv!M7 -> -2.3647201 | M6: =DigInv!N7 -> 0.1 | O6: =ABS(L6-DigInv!$C$34) -> 2.040359 | P6: =M6 -> 0.1
L7: =DigInv!M8 -> -1.9817341 | M7: =DigInv!N8 -> 0.2 | O7: =ABS(L7-DigInv!$C$34) -> 2.4233449 | P7: =M7 -> 0.2
A8: Predicted score: | B8: =DigInv!C27 -> 4.7129471
L9: =DigInv!M9 -> -1.6565685 | M9: =DigInv!N9 -> 0.3 | O9: =ABS(L9-DigInv!$C$34) -> 2.7485105 | P9: =M9 -> 0.3
B10: =RAVLT_Learning!J10 -> Residual variance | C10: =RAVLT_Learning!I10 -> Predicted test score | L10: =DigInv!M10 -> -1.6565057 | M10: =DigInv!N10 -> 0.4 | O10: =ABS(L10-DigInv!$C$34) -> 2.7485733 | P10: =M10 -> 0.4
B11: =DigInv!J11 -> 0 | C11: =DigInv!I11 -> 0 | L11: =DigInv!M11 -> -1.6564429 | M11: =DigInv!N11 -> 0.5 | O11: =ABS(L11-DigInv!$C$34) -> 2.7486362 | P11: =M11 -> 0.5
B12: =DigInv!J12 -> 0 | C12: =DigInv!I12 -> 0 | L12: =DigInv!M12 -> -1.6563973 | M12: =DigInv!N12 -> 0.6 | O12: =ABS(L12-DigInv!$C$34) -> 2.7486817 | P12: =M12 -> 0.6
B13: =DigInv!J13 -> 0 | C13: =DigInv!I13 -> 0 | L13: =DigInv!M13 -> -1.6563917 | M13: =DigInv!N13 -> 0.7 | O13: =ABS(L13-DigInv!$C$34) -> 2.7486873 | P13: =M13 -> 0.7
B14: =DigInv!J14 -> 0 | C14: =DigInv!I14 -> 0 | L14: =DigInv!M14 -> -1.6563861 | M14: =DigInv!N14 -> 0.8 | O14: =ABS(L14-DigInv!$C$34) -> 2.748693 | P14: =M14 -> 0.8
B15: =DigInv!J15 -> 0 | C15: =DigInv!I15 -> 0 | L15: =DigInv!M15 -> -1.6563423 | M15: =DigInv!N15 -> 0.9 | O15: =ABS(L15-DigInv!$C$34) -> 2.7487367 | P15: =M15 -> 0.9
B16: =DigInv!J16 -> 0 | C16: =DigInv!I16 -> 0 | L16: =DigInv!M16 -> -1.6562524 | M16: =DigInv!N16 -> 1 | O16: =ABS(L16-DigInv!$C$34) -> 2.7488266 | P16: =M16 -> 1
B17: =DigInv!J17 -> 0 | C17: =DigInv!I17 -> 0 | L17: =DigInv!M17 -> -1.6561626 | M17: =DigInv!N17 -> 1.1 | O17: =ABS(L17-DigInv!$C$34) -> 2.7489164 | P17: =M17 -> 1.1
B18: =DigInv!J18 -> 0 | C18: =DigInv!I18 -> 0 | L18: =DigInv!M18 -> -1.6559958 | M18: =DigInv!N18 -> 1.2 | O18: =ABS(L18-DigInv!$C$34) -> 2.7490833 | P18: =M18 -> 1.2
B19: =DigInv!J19 -> 0 | C19: =DigInv!I19 -> 0 | L19: =DigInv!M19 -> -1.6557785 | M19: =DigInv!N19 -> 1.3 | O19: =ABS(L19-DigInv!$C$34) -> 2.7493005 | P19: =M19 -> 1.3
B20: =DigInv!J20 -> 0 | C20: =DigInv!I20 -> 0 | E20: Residual variance | G20: {=INDEX(B11:B22,MATCH(MIN(ABS(C11:C22-B8)),ABS(C11:C22-B8),0))} -> 0 | L20: =DigInv!M20 -> -1.6555612 | M20: =DigInv!N20 -> 1.4 | O20: =ABS(L20-DigInv!$C$34) -> 2.7495178 | P20: =M20 -> 1.4
B21: =DigInv!J21 -> 0 | C21: =DigInv!I21 -> 0 | E21: Residual std. Error | G21: =SQRT(G20) -> 0 | L21: =DigInv!M21 -> -1.655508 | M21: =DigInv!N21 -> 1.5 | O21: =ABS(L21-DigInv!$C$34) -> 2.749571 | P21: =M21 -> 1.5
B22: =DigInv!J22 -> 0 | C22: =DigInv!I22 -> 0 | L22: =DigInv!M22 -> -1.655508 | M22: =DigInv!N22 -> 1.6 | O22: =ABS(L22-DigInv!$C$34) -> 2.749571 | P22: =M22 -> 1.6
E23: Formula, see: | F23: https://www.excel-easy.com/examples/closest-match.html | L23: =DigInv!M23 -> -1.655508 | M23: =DigInv!N23 -> 1.7 | O23: =ABS(L23-DigInv!$C$34) -> 2.749571 | P23: =M23 -> 1.7
L24: =DigInv!M24 -> -1.6553426 | M24: =DigInv!N24 -> 1.8 | O24: =ABS(L24-DigInv!$C$34) -> 2.7497364 | P24: =M24 -> 1.8
A25: Not assuming homoscedasticity, variance function | L25: =DigInv!M25 -> -1.6551601 | M25: =DigInv!N25 -> 1.9 | O25: =ABS(L25-DigInv!$C$34) -> 2.7499189 | P25: =M25 -> 1.9
L26: =DigInv!M26 -> -1.6549871 | M26: =DigInv!N26 -> 2 | O26: =ABS(L26-DigInv!$C$34) -> 2.7500919 | P26: =M26 -> 2
A27: =RAVLT_Learning!I26 | B27: =DigInv!J26 -> Estimate | C27: X | D27: Beta x X | L27: =DigInv!M27 -> -1.6549717 | M27: =DigInv!N27 -> 2.1 | O27: =ABS(L27-DigInv!$C$34) -> 2.7501074 | P27: =M27 -> 2.1
A28: =DigInv!I27 -> (Intercept) | B28: =DigInv!J27 -> -232.20989 | C28: 1 | D28: =B28*C28 -> -232.20989 | L28: =DigInv!M28 -> -1.6549562 | M28: =DigInv!N28 -> 2.2 | O28: =ABS(L28-DigInv!$C$34) -> 2.7501228 | P28: =M28 -> 2.2
A29: =DigInv!I28 -> Pred.Y | B29: =DigInv!J28 -> 162.49634 | C29: =B8 -> 4.7129471 | D29: =B29*C29 -> 765.83663 | L29: =DigInv!M29 -> -1.6548812 | M29: =DigInv!N29 -> 2.3 | O29: =ABS(L29-DigInv!$C$34) -> 2.7501978 | P29: =M29 -> 2.3
A30: =DigInv!I29 -> Pred.Y.2 | B30: =DigInv!J29 -> -37.908259 | C30: =B8^2 -> 22.21187 | D30: =B30*C30 -> -842.01332 | L30: =DigInv!M30 -> -1.6545794 | M30: =DigInv!N30 -> 2.4 | O30: =ABS(L30-DigInv!$C$34) -> 2.7504997 | P30: =M30 -> 2.4
A31: =DigInv!I30 -> Pred.Y.3 | B31: =DigInv!J30 -> 2.956833 | C31: =B8^3 -> 104.68337 | D31: =B31*C31 -> 309.53124 | L31: =DigInv!M31 -> -1.6542775 | M31: =DigInv!N31 -> 2.5 | O31: =ABS(L31-DigInv!$C$34) -> 2.7508015 | P31: =M31 -> 2.5
A32: =DigInv!I31 -> 0 | B32: =DigInv!J31 -> 0 | C32: =B8^4 -> 493.36717 | D32: =B32*C32 -> 0 | L32: =DigInv!M32 -> -1.654084 | M32: =DigInv!N32 -> 2.6 | O32: =ABS(L32-DigInv!$C$34) -> 2.750995 | P32: =M32 -> 2.6
A33: =DigInv!I32 -> 0 | B33: =DigInv!J32 -> 0 | C33: =B8^5 -> 2325.2134 | D33: =B33*C33 -> 0 | L33: =DigInv!M33 -> -1.654084 | M33: =DigInv!N33 -> 2.7 | O33: =ABS(L33-DigInv!$C$34) -> 2.750995 | P33: =M33 -> 2.7
G34: =SQRT(D35) -> 1.0698893 | L34: =DigInv!M34 -> -1.654084 | M34: =DigInv!N34 -> 2.8 | O34: =ABS(L34-DigInv!$C$34) -> 2.750995 | P34: =M34 -> 2.8
B35: Predicted VARIANCE | D35: =SUM(D28:D34) -> 1.1446632 | L35: =DigInv!M35 -> -1.6539098 | M35: =DigInv!N35 -> 2.9 | O35: =ABS(L35-DigInv!$C$34) -> 2.7511692 | P35: =M35 -> 2.9
L36: =DigInv!M36 -> -1.6535683 | M36: =DigInv!N36 -> 3 | O36: =ABS(L36-DigInv!$C$34) -> 2.7515107 | P36: =M36 -> 3
A37: Checks | L37: =DigInv!M37 -> -1.6532268 | M37: =DigInv!N37 -> 3.1 | O37: =ABS(L37-DigInv!$C$34) -> 2.7518522 | P37: =M37 -> 3.1
A38: Overall resid std error entered | D38: =IF(G3>0, 1, 0) -> 0 | G38: Res. Std error | I38: =IF(D41=1, G3+G21+G34, ) -> 1.0698893 | L38: =DigInv!M38 -> -1.6528732 | M38: =DigInv!N38 -> 3.2 | O38: =ABS(L38-DigInv!$C$34) -> 2.7522058 | P38: =M38 -> 3.2
A39: Resid std per group | D39: =IF(G21>0, 1, 0) -> 0 | I39: =IF(D41=1, " ", "ERROR!") | L39: =DigInv!M39 -> -1.6525134 | M39: =DigInv!N39 -> 3.3 | O39: =ABS(L39-DigInv!$C$34) -> 2.7525656 | P39: =M39 -> 3.3
A40: Variance function | D40: =IF(G34>0, 1, 0) -> 1 | L40: =DigInv!M40 -> -1.6521537 | M40: =DigInv!N40 -> 3.4 | O40: =ABS(L40-DigInv!$C$34) -> 2.7529254 | P40: =M40 -> 3.4
C41: Som | D41: =SUM(D38:D40) -> 1 | E41: (check should be 1 to be OK) | L41: =DigInv!M41 -> -1.6516645 | M41: =DigInv!N41 -> 3.5 | O41: =ABS(L41-DigInv!$C$34) -> 2.7534145 | P41: =M41 -> 3.5
...

Sheet RAVLT_Rec
B1: ONLY MAKE CHANGES IN THE GREY HIGHLIGHTED CELLS | I1: =#REF! -> #REF!
A3: 1 | B3: COPY-PASTE FINAL STAGE 1 MEAN PREDICTION FUNCTION HERE: | H3: 2 | I3: COPY-PASTE FINAL STAGE 1 VARIANCE PREDICTION FUNCTION HERE: | L3: 3 | M3: COPY-PASTE PERCENTILE RANKS DELTA HERE:
C5: Estimate | H5: A | I5: Assuming homoscedasticity | M5: Delta | N5: Percentile rank
B6: (Intercept) | C6: 12.266165 | I6: Residual variance | M6: -3.376842 | N6: 0
B7: ageC | C7: -0.053962566 | M7: -3.1789388 | N7: 0.1
M8: -2.9810357 | N8: 0.2
H9: B | I9: Not assuming homoscedasticity, prediction-specific residual variances: | M9: -2.836123 | N9: 0.3
I10: Predicted test score | J10: Residual variance | M10: -2.836123 | N10: 0.4
M11: -2.836123 | N11: 0.5
M12: -2.831048 | N12: 0.6
M13: -2.8215711 | N13: 0.7
M14: -2.8120943 | N14: 0.8
M15: -2.8070289 | N15: 0.9
M16: -2.8030439 | N16: 1
M17: -2.7980566 | N17: 1.1
M18: -2.7799627 | N18: 1.2
M19: -2.7618688 | N19: 1.3
M20: -2.7280026 | N20: 1.4
M21: -2.6633553 | N21: 1.5
M22: -2.598708 | N22: 1.6
... M24: -2.4697221 | N24: 1.8
H25: C | I25: Not assuming homoscedasticity, continuous variance prediction function: | M25: -2.4052669 | N25: 1.9
J26: Estimate | M26: -2.3969426 | N26: 2
A27: 4 | B27: Predicted test score: | C27: =C6+(C7*('Normative data'!C6-71.20708447)) -> 16.108682 | I27: (Intercept) | J27: 12426.33 | M27: -2.3966872 | N27: 2.1
B28: [SPECIFY THE APPROPRIATE FORMULA IN CELL B27 TO COMPUTE | I28: Pred.Y | J28: -3071.3827 | M28: -2.396022 | N28: 2.2
B29: THE PREDICTED TEST SCORE BASED ON THE INPUT PROVIDED | I29: Pred.Y.2 | J29: 252.93887 | M29: -2.3928832 | N29: 2.3
B30: IN SHEET 1 (E.G. SPECIFIED GENDER) + COPY-PASTED STAGE 1 MODEL] | I30: Pred.Y.3 | J30: -6.9378657 | M30: -2.3897444 | N30: 2.4
M31: -2.3856358 | N31: 2.5
M32: -2.3801308 | N32: 2.6
B33: Computed residual: | C33: ='Normative data'!#REF!-RAVLT_Rec!C27 -> #REF! | M33: -2.3746258 | N33: 2.7
B34: Std. Residual: | C34: =C33/SD_PERC_RAVLTR!I38 -> #REF! | I34: Residual Std.Error to be used: | J34: =SD_PERC_RAVLTR!I38 -> #NUM! | M34: -2.3710106 | N34: 2.8
M35: -2.3682945 | N35: 2.9
M36: -2.3655784 | N36: 3
M37: -2.3411789 | N37: 3.1
M38: -2.3155259 | N38: 3.2
M39: -2.2820021 | N39: 3.3
M40: -2.2194164 | N40: 3.4
M41: -2.1568308 | N41: 3.5
M42: -2.095222 | N42: 3.6
M43: -2.0346676 | N43: 3.7
...

Sheet RAVLT_Delayed
B1: ONLY MAKE CHANGES IN THE GREY HIGHLIGHTED CELLS | I1: =#REF! -> #REF!
A3: 1 | B3: COPY-PASTE FINAL STAGE 1 MEAN PREDICTION FUNCTION HERE: | H3: 2 | I3: COPY-PASTE FINAL STAGE 1 VARIANCE PREDICTION FUNCTION HERE: | L3: 3 | M3: COPY-PASTE PERCENTILE RANKS DELTA HERE:
C5: Estimate | H5: A | I5: Assuming homoscedasticity | M5: Delta | N5: Percentile rank
B6: (Intercept) | C6: 6.4113082 | I6: Residual variance | M6: -4.7534243 | N6: 0
B7: ageC | C7: -0.12751163 | M7: -3.0902323 | N7: 0.1
B8: sexM | C8: -1.413271 | M8: -2.8781617 | N8: 0.2
B9: years_education | C9: 0.15760791 | H9: B | I9: Not assuming homoscedasticity, prediction-specific residual variances: | M9: -2.7477814 | N9: 0.3
I10: Predicted test score | J10: Residual variance | M10: -2.6520698 | N10: 0.4
M11: -2.5758293 | N11: 0.5
M12: -2.5121443 | N12: 0.6
M13: -2.4572634 | N13: 0.7
M14: -2.4089155 | N14: 0.8
M15: -2.3656181 | N15: 0.9
M16: -2.3263479 | N16: 1
M17: -2.2903679 | N17: 1.1
M18: -2.2571292 | N18: 1.2
M19: -2.2262118 | N19: 1.3
M20: -2.1972864 | N20: 1.4
M21: -2.1700904 | N21: 1.5
M22: -2.1444106 | N22: 1.6
... M24: -2.0969274 | N24: 1.8
H25: C | I25: Not assuming homoscedasticity, continuous variance prediction function: | M25: -2.0748547 | N25: 1.9
J26: Estimate | M26: -2.0537489 | N26: 2
A27: 4 | B27: Predicted test score: | C27: =C6+(C7*('Normative data'!C6-71.28))+(RAVLT_Delayed!C8*'Normative data'!C7)+(C9*'Normative data'!C8) -> 15.500337 | I27: (Intercept) | J27: -59.69921 | M27: -2.0335201 | N27: 2.1
B28: [SPECIFY THE APPROPRIATE FORMULA IN CELL B27 TO COMPUTE | I28: Pred.Y | J28: 29.103683 | M28: -2.0140908 | N28: 2.2
B29: THE PREDICTED TEST SCORE BASED ON THE INPUT PROVIDED | I29: Pred.Y.2 | J29: -4.0759445 | M29: -1.9953933 | N29: 2.3
B30: IN SHEET 1 (E.G. SPECIFIED GENDER) + COPY-PASTED STAGE 1 MODEL] | I30: Pred.Y.3 | J30: 0.18548523 | M30: -1.9773684 | N30: 2.4
M31: -1.959964 | N31: 2.5
M32: -1.9431338 | N32: 2.6
B33: Computed residual: | C33: ='Normative data'!C13-RAVLT_Delayed!C27 -> -15.500337 | M33: -1.9268366 | N33: 2.7
B34: Std. Residual: | C34: =C33/SD_PERC_RAVLTD!I38 -> -1.528048 | I34: Residual Std.Error to be used: | J34: =SD_PERC_RAVLTD!I38 -> 10.143881 | M34: -1.9110356 | N34: 2.8
M35: -1.8956979 | N35: 2.9
M36: -1.8807936 | N36: 3
M37: -1.8662957 | N37: 3.1
M38: -1.8521799 | N38: 3.2
M39: -1.8384237 | N39: 3.3
M40: -1.8250068 | N40: 3.4
M41: -1.8119107 | N41: 3.5
M42: -1.7991181 | N42: 3.6
M43: -1.7866134 | N43: 3.7
...

Sheet SD_PERC_RAVLTR
A1: Determine SD(residual) to use; DO NOT MAKE CHANGES HERE | L1: Determine percentile
A3: Assuming homoscedasticity | G3: =SQRT(RAVLT_Rec!J6) -> 0
L4: =RAVLT_Learning!M5 -> Delta | M4: =RAVLT_Learning!N5 -> Percentile rank | O4: Abs diff delta | P4: Percentile
L5: =RAVLT_Rec!M6 -> -3.376842 | M5: =RAVLT_Rec!N6 -> 0 | O5: =ABS(L5-RAVLT_Rec!$C$34) -> #REF! | P5: =M5 -> 0
A6: Not assuming homoscedasticity, residual std.error per group: | L6: =RAVLT_Rec!M7 -> -3.1789388 | M6: =RAVLT_Rec!N7 -> 0.1 | O6: =ABS(L6-RAVLT_Rec!$C$34) -> #REF! | P6: =M6 -> 0.1
L7: =RAVLT_Rec!M8 -> -2.9810357 | M7: =RAVLT_Rec!N8 -> 0.2 | O7: =ABS(L7-RAVLT_Rec!$C$34) -> #REF! | P7: =M7 -> 0.2
A8: Predicted score: | B8: =RAVLT_Delayed!C27 -> 15.500337
L9: =RAVLT_Rec!M9 -> -2.836123 | M9: =RAVLT_Rec!N9 -> 0.3 | O9: =ABS(L9-RAVLT_Rec!$C$34) -> #REF! | P9: =M9 -> 0.3
B10: =RAVLT_Learning!J10 -> Residual variance | C10: =RAVLT_Learning!I10 -> Predicted test score | L10: =RAVLT_Rec!M10 -> -2.836123 | M10: =RAVLT_Rec!N10 -> 0.4 | O10: =ABS(L10-RAVLT_Rec!$C$34) -> #REF! | P10: =M10 -> 0.4
B11: =RAVLT_Rec!J11 -> 0 | C11: =RAVLT_Rec!I11 -> 0 | L11: =RAVLT_Rec!M11 -> -2.836123 | M11: =RAVLT_Rec!N11 -> 0.5 | O11: =ABS(L11-RAVLT_Rec!$C$34) -> #REF! | P11: =M11 -> 0.5
